Workbook

Sheet orange 1liter
O2: alpha | P2: 0.99786974 | U2: coefii dir | V2: 0.31705914
O3: bet | P3: 0.014081233 | Q3: error2 | R3: =SUM(K21:K110) -> 43.447646 | U3: origine | V3: 58.63147
O4: gamma | P4: 1 | U4: sum | V4: =SUM(Q7:Q70) -> 77203.371
V5: =COUNT($P$2:$P$4) -> 3
D6: period | E6: Y | F6: level | G6: trend | H6: season | I6: forcast | J6: error | K6: abs error | L6: average regression | O6: y | P6: erro | Q6: error2
C7: round3 | D7: 1 | E7: 64.13994 | H7: =E7/$A$44 -> 1.0204608 | M7: =AVERAGE(E7:E21) -> 62.853896 | O7: =$V$2*D7+$V$3 -> 58.948529 | P7: =E7-O7 -> 5.1914109 | Q7: =P7*P7 -> 26.950747
D8: 2 | E8: 26.822157 | H8: =E8/$A$44 -> 0.42673818 | M8: =AVERAGE(E8:E22) -> 63.128181 | O8: =$V$2*D8+$V$3 -> 59.265588 | P8: =E8-O8 -> -32.443431 | Q8: =P8*P8 -> 1052.5762
D9: 3 | E9: 61.80758 | H9: =E9/$A$44 -> 0.9833532 | M9: =AVERAGE(E9:E23) -> 66.70029 | O9: =$V$2*D9+$V$3 -> 59.582647 | P9: =E9-O9 -> 2.2249326 | Q9: =P9*P9 -> 4.9503253
D10: 4 | E10: 13.994169 | H10: =E10/$A$44 -> 0.22264601 | M10: =AVERAGE(E10:E24) -> 67.471072 | O10: =$V$2*D10+$V$3 -> 59.899706 | P10: =E10-O10 -> -45.905537 | Q10: =P10*P10 -> 2107.3184
D11: 5 | E11: 103.79009 | H11: =E11/$A$44 -> 1.6512912 | M11: =AVERAGE(E11:E25) -> 71.19314 | O11: =$V$2*D11+$V$3 -> 60.216766 | P11: =E11-O11 -> 43.573319 | Q11: =P11*P11 -> 1898.6342
D12: 6 | E12: 63.55685 | H12: =E12/$A$44 -> 1.0111839 | M12: =AVERAGE(E12:E26) -> 66.48297 | O12: =$V$2*D12+$V$3 -> 60.533825 | P12: =E12-O12 -> 3.0230252 | Q12: =P12*P12 -> 9.1386815
D13: 7 | E13: 43.731777 | H13: =E13/$A$44 -> 0.69576876 | M13: =AVERAGE(E13:E27) -> 71.419802 | O13: =$V$2*D13+$V$3 -> 60.850884 | P13: =E13-O13 -> -17.119107 | Q13: =P13*P13 -> 293.06382
D14: 8 | E14: 43.14869 | H14: =E14/$A$44 -> 0.68649189 | M14: =AVERAGE(E14:E28) -> 70.253621 | O14: =$V$2*D14+$V$3 -> 61.167943 | P14: =E14-O14 -> -18.019253 | Q14: =P14*P14 -> 324.69348
D15: 9 | E15: 60.6414 | H15: =E15/$A$44 -> 0.96479938 | M15: =AVERAGE(E15:E29) -> 70.292494 | O15: =$V$2*D15+$V$3 -> 61.485002 | P15: =E15-O15 -> -0.8436022 | Q15: =P15*P15 -> 0.71166467
D16: 10 | E16: 149.27113 | H16: =E16/$A$44 -> 2.3748907 | M16: =AVERAGE(E16:E30) -> 69.748276 | O16: =$V$2*D16+$V$3 -> 61.802061 | P16: =E16-O16 -> 87.469069 | Q16: =P16*P16 -> 7650.838
D17: 11 | E17: 85.98479 | H17: =E17/$A$44 -> 1.3680105 | M17: =AVERAGE(E17:E31) -> 62.28472 | O17: =$V$2*D17+$V$3 -> 62.11912 | P17: =E17-O17 -> 23.86567 | Q17: =P17*P17 -> 569.57018
D18: 12 | E18: 33.02206 | H18: =E18/$A$44 -> 0.52537809 | M18: =AVERAGE(E18:E32) -> 60.867269 | O18: =$V$2*D18+$V$3 -> 62.43618 | P18: =E18-O18 -> -29.41412 | Q18: =P18*P18 -> 865.19043
D19: 13 | E19: 104.47395 | H19: =E19/$A$44 -> 1.6621714 | M19: =AVERAGE(E19:E33) -> 60.132465 | O19: =$V$2*D19+$V$3 -> 62.753239 | P19: =E19-O19 -> 41.720711 | Q19: =P19*P19 -> 1740.6177
D20: 14 | E20: 35.811565 | H20: =E20/$A$44 -> 0.56975887 | M20: =AVERAGE(E20:E34) -> 56.434202 | O20: =$V$2*D20+$V$3 -> 63.070298 | P20: =E20-O20 -> -27.258733 | Q20: =P20*P20 -> 743.03852
D21: 15 | E21: 52.612297 | F21: =V3 -> 58.63147 | G21: =V2 -> 0.31705914 | H21: =E21/$A$44 -> 0.83705705 | M21: =AVERAGE(E21:E35) -> 57.313431 | O21: =$V$2*D21+$V$3 -> 63.387357 | P21: =E21-O21 -> -10.77506 | Q21: =P21*P21 -> 116.10192
D22: 16 | E22: 68.25422 | F22: =$P$2*(E22/H7)+(1-$P$2)*(F21+G21) -> 66.868774 | G22: =$P$3*(F22-F21)+(1-$P$3)*G21 -> 0.42858595 | H22: =$P$4*(E22/F22)+(1-$P$4)*H7 -> 1.0207189 | I22: =(F22+(G22))*H7 -> 68.674321 | J22: =E22-I22 -> -0.420101 | K22: =ABS(J22) -> 0.420101 | M22: =AVERAGE(E22:E36) -> 55.672611 | O22: =$V$2*D22+$V$3 -> 63.704416 | P22: =E22-O22 -> 4.5498038 | Q22: =P22*P22 -> 20.700715
D23: 17 | E23: 80.40379 | F23: =$P$2*(E23/H8)+(1-$P$2)*(F22+G22) -> 188.15679 | G23: =$P$3*(F23-F22)+(1-$P$3)*G22 -> 2.1304357 | H23: =$P$4*(E23/F23)+(1-$P$4)*H8 -> 0.42732335 | I23: =(F23+(G23))*H8 -> 81.202825 | J23: =E23-I23 -> -0.79903467 | K23: =ABS(J23) -> 0.79903467 | M23: =AVERAGE(E23:E37) -> 59.455663 | O23: =$V$2*D23+$V$3 -> 64.021475 | P23: =E23-O23 -> 16.382315 | Q23: =P23*P23 -> 268.38023
D24: 18 | E24: 73.36931 | F24: =$P$2*(E24/H9)+(1-$P$2)*(F23+G23) -> 74.85777 | G24: =$P$3*(F24-F23)+(1-$P$3)*G23 -> 0.50504669 | H24: =$P$4*(E24/F24)+(1-$P$4)*H9 -> 0.98011616 | I24: =(F24+(G24))*H9 -> 74.108267 | J24: =E24-I24 -> -0.73895727 | K24: =ABS(J24) -> 0.73895727 | M24: =AVERAGE(E24:E38) -> 58.29541 | O24: =$V$2*D24+$V$3 -> 64.338534 | P24: =E24-O24 -> 9.0307755 | Q24: =P24*P24 -> 81.554907
D25: 19 | E25: 69.82518 | F25: =$P$2*(E25/H10)+(1-$P$2)*(F24+G24) -> 313.10769 | G25: =$P$3*(F25-F24)+(1-$P$3)*G24 -> 3.8527876 | H25: =$P$4*(E25/F25)+(1-$P$4)*H10 -> 0.22300691 | I25: =(F25+(G25))*H10 -> 70.569986 | J25: =E25-I25 -> -0.74480594 | K25: =ABS(J25) -> 0.74480594 | M25: =AVERAGE(E25:E39) -> 58.804123 | O25: =$V$2*D25+$V$3 -> 64.655594 | P25: =E25-O25 -> 5.1695864 | Q25: =P25*P25 -> 26.724623
D26: 20 | E26: 33.137543 | F26: =$P$2*(E26/H11)+(1-$P$2)*(F25+G25) -> 20.700116 | G26: =$P$3*(F26-F25)+(1-$P$3)*G25 -> -0.31892353 | H26: =$P$4*(E26/F26)+(1-$P$4)*H11 -> 1.6008386 | I26: =(F26+(G26))*H11 -> 33.655283 | J26: =E26-I26 -> -0.51773991 | K26: =ABS(J26) -> 0.51773991 | M26: =AVERAGE(E26:E40) -> 58.349111 | O26: =$V$2*D26+$V$3 -> 64.972653 | P26: =E26-O26 -> -31.83511 | Q26: =P26*P26 -> 1013.4742
D27: 21 | E27: 137.60933 | F27: =$P$2*(E27/H12)+(1-$P$2)*(F26+G26) -> 135.84085 | G27: =$P$3*(F27-F26)+(1-$P$3)*G26 -> 1.3068908 | H27: =$P$4*(E27/F27)+(1-$P$4)*H12 -> 1.0130187 | I27: =(F27+(G27))*H12 -> 138.6816 | J27: =E27-I27 -> -1.0722658 | K27: =ABS(J27) -> 1.0722658 | M27: =AVERAGE(E27:E41) -> 64.539941 | O27: =$V$2*D27+$V$3 -> 65.289712 | P27: =E27-O27 -> 72.319618 | Q27: =P27*P27 -> 5230.1272
D28: 22 | E28: 26.239067 | F28: =$P$2*(E28/H13)+(1-$P$2)*(F27+G27) -> 37.924162 | G28: =$P$3*(F28-F27)+(1-$P$3)*G27 -> -0.090299517 | H28: =$P$4*(E28/F28)+(1-$P$4)*H13 -> 0.69188257 | I28: =(F28+(G28))*H13 -> 26.32362 | J28: =E28-I28 -> -0.084552667 | K28: =ABS(J28) -> 0.084552667 | M28: =AVERAGE(E28:E42) -> 62.499319 | O28: =$V$2*D28+$V$3 -> 65.606771 | P28: =E28-O28 -> -39.367704 | Q28: =P28*P28 -> 1549.8161
D29: 23 | E29: 43.731777 | F29: =$P$2*(E29/H14)+(1-$P$2)*(F28+G28) -> 63.648159 | G29: =$P$3*(F29-F28)+(1-$P$3)*G28 -> 0.2731976 | H29: =$P$4*(E29/F29)+(1-$P$4)*H14 -> 0.68708628 | I29: =(F29+(G29))*H14 -> 43.881493 | J29: =E29-I29 -> -0.1497163 | K29: =ABS(J29) -> 0.1497163 | M29: =AVERAGE(E29:E43) -> 64.016715 | O29: =$V$2*D29+$V$3 -> 65.92383 | P29: =E29-O29 -> -22.192053 | Q29: =P29*P29 -> 492.48722
D30: 24 | E30: 52.478134 | F30: =$P$2*(E30/H15)+(1-$P$2)*(F29+G29) -> 54.413092 | G30: =$P$3*(F30-F29)+(1-$P$3)*G29 -> 0.13930951 | H30: =$P$4*(E30/F30)+(1-$P$4)*H15 -> 0.96443947 | I30: =(F30+(G30))*H15 -> 52.632124 | J30: =E30-I30 -> -0.15398957 | K30: =ABS(J30) -> 0.15398957 | M30: =AVERAGE(E30:E44) -> 62.901263 | O30: =$V$2*D30+$V$3 -> 66.240889 | P30: =E30-O30 -> -13.762755 | Q30: =P30*P30 -> 189.41343
D31: 25 | E31: 37.317783 | F31: =$P$2*(E31/H16)+(1-$P$2)*(F30+G30) -> 15.796211 | G31: =$P$3*(F31-F30)+(1-$P$3)*G30 -> -0.40642542 | H31: =$P$4*(E31/F31)+(1-$P$4)*H16 -> 2.3624515 | I31: =(F31+(G31))*H16 -> 36.549059 | J31: =E31-I31 -> 0.76872426 | K31: =ABS(J31) -> 0.76872426 | M31: =AVERAGE(E31:E45) -> 62.202721 | O31: =$V$2*D31+$V$3 -> 66.557948 | P31: =E31-O31 -> -29.240165 | Q31: =P31*P31 -> 854.98728
D32: 26 | E32: 64.72303 | F32: =$P$2*(E32/H17)+(1-$P$2)*(F31+G31) -> 47.243791 | G32: =$P$3*(F32-F31)+(1-$P$3)*G31 -> 0.042118232 | H32: =$P$4*(E32/F32)+(1-$P$4)*H17 -> 1.3699796 | I32: =(F32+(G32))*H17 -> 64.68762 | J32: =E32-I32 -> 0.035409657 | K32: =ABS(J32) -> 0.035409657 | M32: =AVERAGE(E32:E46) -> 65.048202 | O32: =$V$2*D32+$V$3 -> 66.875008 | P32: =E32-O32 -> -2.1519776 | Q32: =P32*P32 -> 4.6310076
C33: round4 | D33: 27 | E33: 22 | F33: =$P$2*(E33/H18)+(1-$P$2)*(F32+G32) -> 41.886132 | G33: =$P$3*(F33-F32)+(1-$P$3)*G32 -> -0.033917282 | H33: =$P$4*(E33/F33)+(1-$P$4)*H18 -> 0.5252335 | I33: =(F33+(G33))*H18 -> 21.988237 | J33: =E33-I33 -> 0.011763099 | K33: =ABS(J33) -> 0.011763099 | M33: =AVERAGE(E33:E47) -> 63.133333 | O33: =$V$2*D33+$V$3 -> 67.192067 | P33: =E33-O33 -> -45.192067 | Q33: =P33*P33 -> 2042.3229
D34: 28 | E34: 49 | F34: =$P$2*(E34/H19)+(1-$P$2)*(F33+G33) -> 29.505868 | G34: =$P$3*(F34-F33)+(1-$P$3)*G33 -> -0.20776907 | H34: =$P$4*(E34/F34)+(1-$P$4)*H19 -> 1.6606866 | I34: =(F34+(G34))*H19 -> 48.698462 | J34: =E34-I34 -> 0.30153776 | K34: =ABS(J34) -> 0.30153776 | M34: =AVERAGE(E34:E48) -> 71.333333 | O34: =$V$2*D34+$V$3 -> 67.509126 | P34: =E34-O34 -> -18.509126 | Q34: =P34*P34 -> 342.58774
D35: 29 | E35: 49 | F35: =$P$2*(E35/H20)+(1-$P$2)*(F34+G34) -> 85.880501 | G35: =$P$3*(F35-F34)+(1-$P$3)*G34 -> 0.5889809 | H35: =$P$4*(E35/F35)+(1-$P$4)*H20 -> 0.57056025 | I35: =(F35+(G35))*H20 -> 49.266754 | J35: =E35-I35 -> -0.26675436 | K35: =ABS(J35) -> 0.26675436 | M35: =AVERAGE(E35:E49) -> 71.333333 | O35: =$V$2*D35+$V$3 -> 67.826185 | P35: =E35-O35 -> -18.826185 | Q35: =P35*P35 -> 354.42524
D36: 30 | E36: 28 | F36: =$P$2*(E36/H21)+(1-$P$2)*(F35+G35) -> 33.563472 | G36: =$P$3*(F36-F35)+(1-$P$3)*G35 -> -0.15600094 | H36: =$P$4*(E36/F36)+(1-$P$4)*H21 -> 0.83424028 | I36: =(F36+(G36))*H21 -> 27.963959 | J36: =E36-I36 -> 0.036040827 | K36: =ABS(J36) -> 0.036040827 | M36: =AVERAGE(E36:E50) -> 71.6 | O36: =$V$2*D36+$V$3 -> 68.143244 | P36: =E36-O36 -> -40.143244 | Q36: =P36*P36 -> 1611.4801
D37: 31 | E37: 125 | F37: =$P$2*(E37/H22)+(1-$P$2)*(F36+G36) -> 122.273 | G37: =$P$3*(F37-F36)+(1-$P$3)*G36 -> 1.0953352 | H37: =$P$4*(E37/F37)+(1-$P$4)*H22 -> 1.0223026 | I37: =(F37+(G37))*H22 -> 125.92439 | J37: =E37-I37 -> -0.92438764 | K37: =ABS(J37) -> 0.92438764 | M37: =AVERAGE(E37:E51) -> 82.533333 | O37: =$V$2*D37+$V$3 -> 68.460303 | P37: =E37-O37 -> 56.539697 | Q37: =P37*P37 -> 3196.7373
D38: 32 | E38: 63 | F38: =$P$2*(E38/H23)+(1-$P$2)*(F37+G37) -> 147.37809 | G38: =$P$3*(F38-F37)+(1-$P$3)*G37 -> 1.4334222 | H38: =$P$4*(E38/F38)+(1-$P$4)*H23 -> 0.42747196 | I38: =(F38+(G38))*H23 -> 63.590632 | J38: =E38-I38 -> -0.59063174 | K38: =ABS(J38) -> 0.59063174 | M38: =AVERAGE(E38:E52) -> 77.933333 | O38: =$V$2*D38+$V$3 -> 68.777362 | P38: =E38-O38 -> -5.7773624 | Q38: =P38*P38 -> 33.377917
D39: 33 | E39: 81 | F39: =$P$2*(E39/H24)+(1-$P$2)*(F38+G38) -> 82.784221 | G39: =$P$3*(F39-F38)+(1-$P$3)*G38 -> 0.50367656 | H39: =$P$4*(E39/F39)+(1-$P$4)*H24 -> 0.97844733 | I39: =(F39+(G39))*H24 -> 81.631815 | J39: =E39-I39 -> -0.63181458 | K39: =ABS(J39) -> 0.63181458 | M39: =AVERAGE(E39:E53) -> 77.866667 | O39: =$V$2*D39+$V$3 -> 69.094422 | P39: =E39-O39 -> 11.905578 | Q39: =P39*P39 -> 141.7428
D40: 34 | E40: 63 | F40: =$P$2*(E40/H25)+(1-$P$2)*(F39+G39) -> 282.07808 | G40: =$P$3*(F40-F39)+(1-$P$3)*G39 -> 3.3028873 | H40: =$P$4*(E40/F40)+(1-$P$4)*H25 -> 0.22334242 | I40: =(F40+(G40))*H25 -> 63.641927 | J40: =E40-I40 -> -0.64192714 | K40: =ABS(J40) -> 0.64192714 | M40: =AVERAGE(E40:E54) -> 77.4 | O40: =$V$2*D40+$V$3 -> 69.411481 | P40: =E40-O40 -> -6.4114807 | Q40: =P40*P40 -> 41.107085
D41: 35 | E41: 126 | F41: =$P$2*(E41/H26)+(1-$P$2)*(F40+G40) -> 79.149015 | G41: =$P$3*(F41-F40)+(1-$P$3)*G40 -> 0.39888726 | H41: =$P$4*(E41/F41)+(1-$P$4)*H26 -> 1.5919339 | I41: =(F41+(G41))*H26 -> 127.34335 | J41: =E41-I41 -> -1.3433493 | K41: =ABS(J41) -> 1.3433493 | M41: =AVERAGE(E41:E55) -> 79 | O41: =$V$2*D41+$V$3 -> 69.72854 | P41: =E41-O41 -> 56.27146 | Q41: =P41*P41 -> 3166.4772
...

Sheet orange mango1liter
O2: alpha | P2: 0.99912968 | U2: coefii dir | V2: 0
O3: bet | P3: 0.002600099 | Q3: error2 | R3: =SUM(K21:K84) -> 3.4844723 | U3: origine | V3: 41.459281
O4: gamma | P4: 1 | U4: sum | V4: =SUM(Q7:Q70) -> 28456.864
V5: =COUNT($P$2:$P$4) -> 3
D6: period | E6: Y | F6: level | G6: trend | H6: season | I6: forcast | J6: error | K6: abs error | L6: average regression | O6: y | P6: erro | Q6: error2
C7: round3 | D7: 1 | E7: 68.60465 | H7: =E7/$A$44 -> 1.6121831 | M7: =AVERAGE(E7:E21) -> 42.553883 | O7: =$V$2*D7+$V$3 -> 41.459281 | P7: =E7-O7 -> 27.145369 | Q7: =P7*P7 -> 736.87108
D8: 2 | E8: 97.093025 | H8: =E8/$A$44 -> 2.281649 | M8: =AVERAGE(E8:E22) -> 40.697003 | O8: =$V$2*D8+$V$3 -> 41.459281 | P8: =E8-O8 -> 55.633744 | Q8: =P8*P8 -> 3095.1135
D9: 3 | E9: 29.069767 | H9: =E9/$A$44 -> 0.68312842 | M9: =AVERAGE(E9:E23) -> 35.091186 | O9: =$V$2*D9+$V$3 -> 41.459281 | P9: =E9-O9 -> -12.389514 | Q9: =P9*P9 -> 153.50005
D10: 4 | E10: 27.906977 | H10: =E10/$A$44 -> 0.6558033 | M10: =AVERAGE(E10:E24) -> 35.253395 | O10: =$V$2*D10+$V$3 -> 41.459281 | P10: =E10-O10 -> -13.552304 | Q10: =P10*P10 -> 183.66493
D11: 5 | E11: 18.89535 | H11: =E11/$A$44 -> 0.44403351 | M11: =AVERAGE(E11:E25) -> 36.456513 | O11: =$V$2*D11+$V$3 -> 41.459281 | P11: =E11-O11 -> -22.563931 | Q11: =P11*P11 -> 509.13097
D12: 6 | E12: 16.569767 | H12: =E12/$A$44 -> 0.3893832 | M12: =AVERAGE(E12:E26) -> 36.776785 | O12: =$V$2*D12+$V$3 -> 41.459281 | P12: =E12-O12 -> -24.889514 | Q12: =P12*P12 -> 619.48789
D13: 7 | E13: 94.476746 | H13: =E13/$A$44 -> 2.2201675 | M13: =AVERAGE(E13:E27) -> 39.233882 | O13: =$V$2*D13+$V$3 -> 41.459281 | P13: =E13-O13 -> 53.017465 | Q13: =P13*P13 -> 2810.8516
D14: 8 | E14: 15.406977 | H14: =E14/$A$44 -> 0.36205808 | M14: =AVERAGE(E14:E28) -> 35.853235 | O14: =$V$2*D14+$V$3 -> 41.459281 | P14: =E14-O14 -> -26.052304 | Q14: =P14*P14 -> 678.72252
D15: 9 | E15: 87.5 | H15: =E15/$A$44 -> 2.0562166 | M15: =AVERAGE(E15:E29) -> 39.271038 | O15: =$V$2*D15+$V$3 -> 41.459281 | P15: =E15-O15 -> 46.040719 | Q15: =P15*P15 -> 2119.7478
D16: 10 | E16: 21.802326 | H16: =E16/$A$44 -> 0.51234634 | M16: =AVERAGE(E16:E30) -> 37.219982 | O16: =$V$2*D16+$V$3 -> 41.459281 | P16: =E16-O16 -> -19.656955 | Q16: =P16*P16 -> 386.39587
D17: 11 | E17: 33.526012 | H17: =E17/$A$44 -> 0.78784848 | M17: =AVERAGE(E17:E31) -> 40.126424 | O17: =$V$2*D17+$V$3 -> 41.459281 | P17: =E17-O17 -> -7.9332686 | Q17: =P17*P17 -> 62.936751
D18: 12 | E18: 16.473988 | H18: =E18/$A$44 -> 0.38713243 | M18: =AVERAGE(E18:E32) -> 38.836158 | O18: =$V$2*D18+$V$3 -> 41.459281 | P18: =E18-O18 -> -24.985293 | Q18: =P18*P18 -> 624.26485
D19: 13 | E19: 29.190752 | H19: =E19/$A$44 -> 0.68597153 | M19: =AVERAGE(E19:E33) -> 38.537892 | O19: =$V$2*D19+$V$3 -> 41.459281 | P19: =E19-O19 -> -12.268529 | Q19: =P19*P19 -> 150.51679
D20: 14 | E20: 52.312138 | H20: =E20/$A$44 -> 1.2293153 | M20: =AVERAGE(E20:E34) -> 38.525175 | O20: =$V$2*D20+$V$3 -> 41.459281 | P20: =E20-O20 -> 10.852857 | Q20: =P20*P20 -> 117.78451
D21: 15 | E21: 29.479769 | F21: =V3 -> 41.459281 | G21: =V2 -> 0 | H21: =E21/$A$44 -> 0.69276331 | M21: =AVERAGE(E21:E35) -> 38.037699 | O21: =$V$2*D21+$V$3 -> 41.459281 | P21: =E21-O21 -> -11.979512 | Q21: =P21*P21 -> 143.5087
D22: 16 | E22: 40.751446 | F22: =$P$2*(E22/H7)+(1-$P$2)*(F21+G21) -> 25.291266 | G22: =$P$3*(F22-F21)+(1-$P$3)*G21 -> -0.042038437 | H22: =$P$4*(E22/F22)+(1-$P$4)*H7 -> 1.6112853 | I22: =(F22+(G22))*H7 -> 40.706378 | J22: =E22-I22 -> 0.045068183 | K22: =ABS(J22) -> 0.045068183 | M22: =AVERAGE(E22:E36) -> 37.672381 | O22: =$V$2*D22+$V$3 -> 41.459281 | P22: =E22-O22 -> -0.70783462 | Q22: =P22*P22 -> 0.50102986
D23: 17 | E23: 13.00578 | F23: =$P$2*(E23/H8)+(1-$P$2)*(F22+G22) -> 5.7171809 | G23: =$P$3*(F23-F22)+(1-$P$3)*G22 -> -0.092823692 | H23: =$P$4*(E23/F23)+(1-$P$4)*H8 -> 2.2748589 | I23: =(F23+(G23))*H8 -> 12.832809 | J23: =E23-I23 -> 0.17297103 | K23: =ABS(J23) -> 0.17297103 | M23: =AVERAGE(E23:E37) -> 38.622285 | O23: =$V$2*D23+$V$3 -> 41.459281 | P23: =E23-O23 -> -28.453501 | Q23: =P23*P23 -> 809.6017
D24: 18 | E24: 31.50289 | F24: =$P$2*(E24/H9)+(1-$P$2)*(F23+G23) -> 46.080378 | G24: =$P$3*(F24-F23)+(1-$P$3)*G23 -> 0.012365966 | H24: =$P$4*(E24/F24)+(1-$P$4)*H9 -> 0.68365086 | I24: =(F24+(G24))*H9 -> 31.487264 | J24: =E24-I24 -> 0.01562628 | K24: =ABS(J24) -> 0.01562628 | M24: =AVERAGE(E24:E38) -> 40.755233 | O24: =$V$2*D24+$V$3 -> 41.459281 | P24: =E24-O24 -> -9.9563906 | Q24: =P24*P24 -> 99.129714
D25: 19 | E25: 45.95376 | F25: =$P$2*(E25/H10)+(1-$P$2)*(F24+G24) -> 70.051604 | G25: =$P$3*(F25-F24)+(1-$P$3)*G24 -> 0.074661372 | H25: =$P$4*(E25/F25)+(1-$P$4)*H10 -> 0.65599868 | I25: =(F25+(G25))*H10 -> 45.989036 | J25: =E25-I25 -> -0.035276458 | K25: =ABS(J25) -> 0.035276458 | M25: =AVERAGE(E25:E39) -> 42.921707 | O25: =$V$2*D25+$V$3 -> 41.459281 | P25: =E25-O25 -> 4.4944794 | Q25: =P25*P25 -> 20.200345
D26: 20 | E26: 23.699423 | F26: =$P$2*(E26/H11)+(1-$P$2)*(F25+G25) -> 53.387631 | G26: =$P$3*(F26-F25)+(1-$P$3)*G25 -> 0.031139267 | H26: =$P$4*(E26/F26)+(1-$P$4)*H11 -> 0.44391224 | I26: =(F26+(G26))*H11 -> 23.719724 | J26: =E26-I26 -> -0.020301215 | K26: =ABS(J26) -> 0.020301215 | M26: =AVERAGE(E26:E40) -> 43.658123 | O26: =$V$2*D26+$V$3 -> 41.459281 | P26: =E26-O26 -> -17.759858 | Q26: =P26*P26 -> 315.41254
D27: 21 | E27: 53.426224 | F27: =$P$2*(E27/H12)+(1-$P$2)*(F26+G26) -> 137.13439 | G27: =$P$3*(F27-F26)+(1-$P$3)*G26 -> 0.24880817 | H27: =$P$4*(E27/F27)+(1-$P$4)*H12 -> 0.38959026 | I27: =(F27+(G27))*H12 -> 53.494711 | J27: =E27-I27 -> -0.068486631 | K27: =ABS(J27) -> 0.068486631 | M27: =AVERAGE(E27:E41) -> 46.411494 | O27: =$V$2*D27+$V$3 -> 41.459281 | P27: =E27-O27 -> 11.966943 | Q27: =P27*P27 -> 143.20773
D28: 22 | E28: 43.76704 | F28: =$P$2*(E28/H13)+(1-$P$2)*(F27+G27) -> 19.815807 | G28: =$P$3*(F28-F27)+(1-$P$3)*G27 -> -0.056878689 | H28: =$P$4*(E28/F28)+(1-$P$4)*H13 -> 2.2086933 | I28: =(F28+(G28))*H13 -> 43.868129 | J28: =E28-I28 -> -0.10108927 | K28: =ABS(J28) -> 0.10108927 | M28: =AVERAGE(E28:E42) -> 43.849746 | O28: =$V$2*D28+$V$3 -> 41.459281 | P28: =E28-O28 -> 2.3077594 | Q28: =P28*P28 -> 5.3257533
D29: 23 | E29: 66.67402 | F29: =$P$2*(E29/H14)+(1-$P$2)*(F28+G28) -> 184.00976 | G29: =$P$3*(F29-F28)+(1-$P$3)*G28 -> 0.37018972 | H29: =$P$4*(E29/F29)+(1-$P$4)*H14 -> 0.36233959 | I29: =(F29+(G29))*H14 -> 66.756248 | J29: =E29-I29 -> -0.082228317 | K29: =ABS(J29) -> 0.082228317 | M29: =AVERAGE(E29:E43) -> 42.865277 | O29: =$V$2*D29+$V$3 -> 41.459281 | P29: =E29-O29 -> 25.214739 | Q29: =P29*P29 -> 635.78308
D30: 24 | E30: 56.73416 | F30: =$P$2*(E30/H15)+(1-$P$2)*(F29+G29) -> 27.727986 | G30: =$P$3*(F30-F29)+(1-$P$3)*G29 -> -0.03712088 | H30: =$P$4*(E30/F30)+(1-$P$4)*H15 -> 2.0460974 | I30: =(F30+(G30))*H15 -> 56.938416 | J30: =E30-I30 -> -0.20425629 | K30: =ABS(J30) -> 0.20425629 | M30: =AVERAGE(E30:E44) -> 41.087009 | O30: =$V$2*D30+$V$3 -> 41.459281 | P30: =E30-O30 -> 15.274879 | Q30: =P30*P30 -> 233.32194
D31: 25 | E31: 65.39896 | F31: =$P$2*(E31/H16)+(1-$P$2)*(F30+G30) -> 127.55901 | G31: =$P$3*(F31-F30)+(1-$P$3)*G30 -> 0.22254617 | H31: =$P$4*(E31/F31)+(1-$P$4)*H16 -> 0.51269575 | I31: =(F31+(G31))*H16 -> 65.46841 | J31: =E31-I31 -> -0.069449943 | K31: =ABS(J31) -> 0.069449943 | M31: =AVERAGE(E31:E45) -> 38.438065 | O31: =$V$2*D31+$V$3 -> 41.459281 | P31: =E31-O31 -> 23.939679 | Q31: =P31*P31 -> 573.10825
D32: 26 | E32: 14.172013 | F32: =$P$2*(E32/H17)+(1-$P$2)*(F31+G31) -> 18.083803 | G32: =$P$3*(F32-F31)+(1-$P$3)*G31 -> -0.062678835 | H32: =$P$4*(E32/F32)+(1-$P$4)*H17 -> 0.78368544 | I32: =(F32+(G32))*H17 -> 14.197915 | J32: =E32-I32 -> -0.025902102 | K32: =ABS(J32) -> 0.025902102 | M32: =AVERAGE(E32:E46) -> 37.744801 | O32: =$V$2*D32+$V$3 -> 41.459281 | P32: =E32-O32 -> -27.287268 | Q32: =P32*P32 -> 744.59497
C33: round4 | D33: 27 | E33: 12 | F33: =$P$2*(E33/H18)+(1-$P$2)*(F32+G32) -> 30.985852 | G33: =$P$3*(F33-F32)+(1-$P$3)*G32 -> -0.02896926 | H33: =$P$4*(E33/F33)+(1-$P$4)*H18 -> 0.38727352 | I33: =(F33+(G33))*H18 -> 11.984413 | J33: =E33-I33 -> 0.015586964 | K33: =ABS(J33) -> 0.015586964 | M33: =AVERAGE(E33:E47) -> 42.533333 | O33: =$V$2*D33+$V$3 -> 41.459281 | P33: =E33-O33 -> -29.459281 | Q33: =P33*P33 -> 867.84921
D34: 28 | E34: 29 | F34: =$P$2*(E34/H19)+(1-$P$2)*(F33+G33) -> 42.265956 | G34: =$P$3*(F34-F33)+(1-$P$3)*G33 -> 0.00043545058 | H34: =$P$4*(E34/F34)+(1-$P$4)*H19 -> 0.68613141 | I34: =(F34+(G34))*H19 -> 28.993541 | J34: =E34-I34 -> 0.0064588962 | K34: =ABS(J34) -> 0.0064588962 | M34: =AVERAGE(E34:E48) -> 43 | O34: =$V$2*D34+$V$3 -> 41.459281 | P34: =E34-O34 -> -12.459281 | Q34: =P34*P34 -> 155.23367
D35: 29 | E35: 45 | F35: =$P$2*(E35/H20)+(1-$P$2)*(F34+G34) -> 36.610671 | G35: =$P$3*(F35-F34)+(1-$P$3)*G34 -> -0.014269984 | H35: =$P$4*(E35/F35)+(1-$P$4)*H20 -> 1.2291498 | I35: =(F35+(G35))*H20 -> 44.988514 | J35: =E35-I35 -> 0.011485961 | K35: =ABS(J35) -> 0.011485961 | M35: =AVERAGE(E35:E49) -> 43 | O35: =$V$2*D35+$V$3 -> 41.459281 | P35: =E35-O35 -> 3.5407194 | Q35: =P35*P35 -> 12.536694
D36: 30 | E36: 24 | F36: =$P$2*(E36/H21)+(1-$P$2)*(F35+G35) -> 34.645566 | G36: =$P$3*(F36-F35)+(1-$P$3)*G35 -> -0.019342346 | H36: =$P$4*(E36/F36)+(1-$P$4)*H21 -> 0.69272934 | I36: =(F36+(G36))*H21 -> 23.987778 | J36: =E36-I36 -> 0.012222428 | K36: =ABS(J36) -> 0.012222428 | M36: =AVERAGE(E36:E50) -> 42.466667 | O36: =$V$2*D36+$V$3 -> 41.459281 | P36: =E36-O36 -> -17.459281 | Q36: =P36*P36 -> 304.82648
D37: 31 | E37: 55 | F37: =$P$2*(E37/H22)+(1-$P$2)*(F36+G36) -> 34.134668 | G37: =$P$3*(F37-F36)+(1-$P$3)*G36 -> -0.020620439 | H37: =$P$4*(E37/F37)+(1-$P$4)*H22 -> 1.6112651 | I37: =(F37+(G37))*H22 -> 54.967465 | J37: =E37-I37 -> 0.032535482 | K37: =ABS(J37) -> 0.032535482 | M37: =AVERAGE(E37:E51) -> 43.133333 | O37: =$V$2*D37+$V$3 -> 41.459281 | P37: =E37-O37 -> 13.540719 | Q37: =P37*P37 -> 183.35108
D38: 32 | E38: 45 | F38: =$P$2*(E38/H23)+(1-$P$2)*(F37+G37) -> 19.79392 | G38: =$P$3*(F38-F37)+(1-$P$3)*G37 -> -0.057854188 | H38: =$P$4*(E38/F38)+(1-$P$4)*H23 -> 2.2734253 | I38: =(F38+(G38))*H23 -> 44.896767 | J38: =E38-I38 -> 0.10323348 | K38: =ABS(J38) -> 0.10323348 | M38: =AVERAGE(E38:E52) -> 42.333333 | O38: =$V$2*D38+$V$3 -> 41.459281 | P38: =E38-O38 -> 3.5407194 | Q38: =P38*P38 -> 12.536694
D39: 33 | E39: 64 | F39: =$P$2*(E39/H24)+(1-$P$2)*(F38+G38) -> 93.550738 | G39: =$P$3*(F39-F38)+(1-$P$3)*G38 -> 0.13407126 | H39: =$P$4*(E39/F39)+(1-$P$4)*H24 -> 0.68412074 | I39: =(F39+(G39))*H24 -> 64.0477 | J39: =E39-I39 -> -0.047700068 | K39: =ABS(J39) -> 0.047700068 | M39: =AVERAGE(E39:E53) -> 41.866667 | O39: =$V$2*D39+$V$3 -> 41.459281 | P39: =E39-O39 -> 22.540719 | Q39: =P39*P39 -> 508.08403
D40: 34 | E40: 57 | F40: =$P$2*(E40/H25)+(1-$P$2)*(F39+G39) -> 86.896332 | G40: =$P$3*(F40-F39)+(1-$P$3)*G39 -> 0.11642055 | H40: =$P$4*(E40/F40)+(1-$P$4)*H25 -> 0.65595404 | I40: =(F40+(G40))*H25 -> 57.080251 | J40: =E40-I40 -> -0.080250862 | K40: =ABS(J40) -> 0.080250862 | M40: =AVERAGE(E40:E54) -> 42 | O40: =$V$2*D40+$V$3 -> 41.459281 | P40: =E40-O40 -> 15.540719 | Q40: =P40*P40 -> 241.51396
D41: 35 | E41: 65 | F41: =$P$2*(E41/H26)+(1-$P$2)*(F40+G40) -> 146.37363 | G41: =$P$3*(F41-F40)+(1-$P$3)*G40 -> 0.27076471 | H41: =$P$4*(E41/F41)+(1-$P$4)*H26 -> 0.44406906 | I41: =(F41+(G41))*H26 -> 65.097242 | J41: =E41-I41 -> -0.097241842 | K41: =ABS(J41) -> 0.097241842 | M41: =AVERAGE(E41:E55) -> 40.333333 | O41: =$V$2*D41+$V$3 -> 41.459281 | P41: =E41-O41 -> 23.540719 | Q41: =P41*P41 -> 554.16547
...

Sheet orange cpower1liter
O2: alpha | P2: 1 | U2: coefii dir | V2: 0
O3: bet | P3: 0 | Q3: error2 | R3: =SUM(K21:K84) -> 1.2718993e-14 | U3: origine | V3: 11.09902
O4: gamma | P4: 1 | U4: sum | V4: =SUM(Q7:Q70) -> 3097.6766
V5: =COUNT($P$2:$P$4) -> 3
D6: period | E6: Y | F6: level | G6: trend | H6: season | I6: forcast | J6: error | K6: abs error | L6: average regression | O6: y | P6: erro | Q6: error2
C7: round3 | D7: 1 | E7: 24.043478 | H7: =E7/$A$44 -> 2.1294431 | M7: =AVERAGE(E7:E21) -> 11.29097 | O7: =$V$2*D7+$V$3 -> 11.09902 | P7: =E7-O7 -> 12.944458 | Q7: =P7*P7 -> 167.55899
D8: 2 | E8: 2.3333333 | H8: =E8/$A$44 -> 0.20665481 | M8: =AVERAGE(E8:E22) -> 10.440979 | O8: =$V$2*D8+$V$3 -> 11.09902 | P8: =E8-O8 -> -8.7656868 | Q8: =P8*P8 -> 76.837266
D9: 3 | E9: 6.3913045 | H9: =E9/$A$44 -> 0.5660545 | M9: =AVERAGE(E9:E23) -> 10.895888 | O9: =$V$2*D9+$V$3 -> 11.09902 | P9: =E9-O9 -> -4.7077156 | Q9: =P9*P9 -> 22.162586
D10: 4 | E10: 11.362319 | H10: =E10/$A$44 -> 1.0063191 | M10: =AVERAGE(E10:E24) -> 11.127747 | O10: =$V$2*D10+$V$3 -> 11.09902 | P10: =E10-O10 -> 0.26329887 | Q10: =P10*P10 -> 0.069326295
D11: 5 | E11: 11.057971 | H11: =E11/$A$44 -> 0.97936412 | M11: =AVERAGE(E11:E25) -> 11.285957 | O11: =$V$2*D11+$V$3 -> 11.09902 | P11: =E11-O11 -> -0.04104913 | Q11: =P11*P11 -> 0.0016850311
D12: 6 | E12: 14.304348 | H12: =E12/$A$44 -> 1.2668839 | M12: =AVERAGE(E12:E26) -> 11.132092 | O12: =$V$2*D12+$V$3 -> 11.09902 | P12: =E12-O12 -> 3.2053279 | Q12: =P12*P12 -> 10.274127
D13: 7 | E13: 18.057972 | H13: =E13/$A$44 -> 1.5993286 | M13: =AVERAGE(E13:E27) -> 10.476307 | O13: =$V$2*D13+$V$3 -> 11.09902 | P13: =E13-O13 -> 6.9589519 | Q13: =P13*P13 -> 48.427011
D14: 8 | E14: 7.811594 | H14: =E14/$A$44 -> 0.69184436 | M14: =AVERAGE(E14:E28) -> 10.74302 | O14: =$V$2*D14+$V$3 -> 11.09902 | P14: =E14-O14 -> -3.2874261 | Q14: =P14*P14 -> 10.807171
D15: 9 | E15: 16.130434 | H15: =E15/$A$44 -> 1.4286136 | M15: =AVERAGE(E15:E29) -> 10.545843 | O15: =$V$2*D15+$V$3 -> 11.09902 | P15: =E15-O15 -> 5.0314139 | Q15: =P15*P15 -> 25.315126
D16: 10 | E16: 7.1014495 | H16: =E16/$A$44 -> 0.62894945 | M16: =AVERAGE(E16:E30) -> 10.39036 | O16: =$V$2*D16+$V$3 -> 11.09902 | P16: =E16-O16 -> -3.9975706 | Q16: =P16*P16 -> 15.980571
D17: 11 | E17: 10.174418 | H17: =E17/$A$44 -> 0.90111105 | M17: =AVERAGE(E17:E31) -> 11.887413 | O17: =$V$2*D17+$V$3 -> 11.09902 | P17: =E17-O17 -> -0.92460213 | Q17: =P17*P17 -> 0.8548891
D18: 12 | E18: 3.2558138 | H18: =E18/$A$44 -> 0.28835554 | M18: =AVERAGE(E18:E32) -> 11.564578 | O18: =$V$2*D18+$V$3 -> 11.09902 | P18: =E18-O18 -> -7.8432063 | Q18: =P18*P18 -> 61.515886
D19: 13 | E19: 13.430233 | H19: =E19/$A$44 -> 1.1894667 | M19: =AVERAGE(E19:E33) -> 12.480857 | O19: =$V$2*D19+$V$3 -> 11.09902 | P19: =E19-O19 -> 2.3312129 | Q19: =P19*P19 -> 5.4345534
D20: 14 | E20: 14.040698 | H20: =E20/$A$44 -> 1.2435334 | M20: =AVERAGE(E20:E34) -> 12.118842 | O20: =$V$2*D20+$V$3 -> 11.09902 | P20: =E20-O20 -> 2.9416779 | Q20: =P20*P20 -> 8.6534687
D21: 15 | E21: 9.869186 | F21: =V3 -> 11.09902 | G21: =V2 -> 0 | H21: =E21/$A$44 -> 0.87407777 | M21: =AVERAGE(E21:E35) -> 11.916128 | O21: =$V$2*D21+$V$3 -> 11.09902 | P21: =E21-O21 -> -1.2298341 | Q21: =P21*P21 -> 1.512492
D22: 16 | E22: 11.293605 | F22: =$P$2*(E22/H7)+(1-$P$2)*(F21+G21) -> 5.3035487 | G22: =$P$3*(F22-F21)+(1-$P$3)*G21 -> 0 | H22: =$P$4*(E22/F22)+(1-$P$4)*H7 -> 2.1294431 | I22: =(F22+(G22))*H7 -> 11.293605 | J22: =E22-I22 -> 0 | K22: =ABS(J22) -> 0 | M22: =AVERAGE(E22:E36) -> 11.324849 | O22: =$V$2*D22+$V$3 -> 11.09902 | P22: =E22-O22 -> 0.19458487 | Q22: =P22*P22 -> 0.037863271
D23: 17 | E23: 9.156977 | F23: =$P$2*(E23/H8)+(1-$P$2)*(F22+G22) -> 44.310495 | G23: =$P$3*(F23-F22)+(1-$P$3)*G22 -> 0 | H23: =$P$4*(E23/F23)+(1-$P$4)*H8 -> 0.20665481 | I23: =(F23+(G23))*H8 -> 9.156977 | J23: =E23-I23 -> 0 | K23: =ABS(J23) -> 0 | M23: =AVERAGE(E23:E37) -> 11.238609 | O23: =$V$2*D23+$V$3 -> 11.09902 | P23: =E23-O23 -> -1.9420431 | Q23: =P23*P23 -> 3.7715315
D24: 18 | E24: 9.869186 | F24: =$P$2*(E24/H9)+(1-$P$2)*(F23+G23) -> 17.435045 | G24: =$P$3*(F24-F23)+(1-$P$3)*G23 -> 0 | H24: =$P$4*(E24/F24)+(1-$P$4)*H9 -> 0.5660545 | I24: =(F24+(G24))*H9 -> 9.869186 | J24: =E24-I24 -> 0 | K24: =ABS(J24) -> 0 | M24: =AVERAGE(E24:E38) -> 11.361477 | O24: =$V$2*D24+$V$3 -> 11.09902 | P24: =E24-O24 -> -1.2298341 | Q24: =P24*P24 -> 1.512492
D25: 19 | E25: 13.735465 | F25: =$P$2*(E25/H10)+(1-$P$2)*(F24+G24) -> 13.649214 | G25: =$P$3*(F25-F24)+(1-$P$3)*G24 -> 0 | H25: =$P$4*(E25/F25)+(1-$P$4)*H10 -> 1.0063191 | I25: =(F25+(G25))*H10 -> 13.735465 | J25: =E25-I25 -> 0 | K25: =ABS(J25) -> 0 | M25: =AVERAGE(E25:E39) -> 10.770198 | O25: =$V$2*D25+$V$3 -> 11.09902 | P25: =E25-O25 -> 2.6364449 | Q25: =P25*P25 -> 6.9508416
D26: 20 | E26: 8.75 | F26: =$P$2*(E26/H11)+(1-$P$2)*(F25+G25) -> 8.9343686 | G26: =$P$3*(F26-F25)+(1-$P$3)*G25 -> 0 | H26: =$P$4*(E26/F26)+(1-$P$4)*H11 -> 0.97936412 | I26: =(F26+(G26))*H11 -> 8.75 | J26: =E26-I26 -> 0 | K26: =ABS(J26) -> 0 | M26: =AVERAGE(E26:E40) -> 11.921167 | O26: =$V$2*D26+$V$3 -> 11.09902 | P26: =E26-O26 -> -2.3490201 | Q26: =P26*P26 -> 5.5178956
D27: 21 | E27: 4.4675746 | F27: =$P$2*(E27/H12)+(1-$P$2)*(F26+G26) -> 3.5264279 | G27: =$P$3*(F27-F26)+(1-$P$3)*G26 -> 0 | H27: =$P$4*(E27/F27)+(1-$P$4)*H12 -> 1.2668839 | I27: =(F27+(G27))*H12 -> 4.4675746 | J27: =E27-I27 -> 0 | K27: =ABS(J27) -> 0 | M27: =AVERAGE(E27:E41) -> 12.071167 | O27: =$V$2*D27+$V$3 -> 11.09902 | P27: =E27-O27 -> -6.6314455 | Q27: =P27*P27 -> 43.97607
D28: 22 | E28: 22.05867 | F28: =$P$2*(E28/H13)+(1-$P$2)*(F27+G27) -> 13.792456 | G28: =$P$3*(F28-F27)+(1-$P$3)*G27 -> 0 | H28: =$P$4*(E28/F28)+(1-$P$4)*H13 -> 1.5993286 | I28: =(F28+(G28))*H13 -> 22.05867 | J28: =E28-I28 -> 0 | K28: =ABS(J28) -> 0 | M28: =AVERAGE(E28:E42) -> 12.239995 | O28: =$V$2*D28+$V$3 -> 11.09902 | P28: =E28-O28 -> 10.95965 | Q28: =P28*P28 -> 120.11393
D29: 23 | E29: 4.853928 | F29: =$P$2*(E29/H14)+(1-$P$2)*(F28+G28) -> 7.0159248 | G29: =$P$3*(F29-F28)+(1-$P$3)*G28 -> 0 | H29: =$P$4*(E29/F29)+(1-$P$4)*H14 -> 0.69184436 | I29: =(F29+(G29))*H14 -> 4.853928 | J29: =E29-I29 -> 0 | K29: =ABS(J29) -> 0 | M29: =AVERAGE(E29:E43) -> 11.302751 | O29: =$V$2*D29+$V$3 -> 11.09902 | P29: =E29-O29 -> -6.2450921 | Q29: =P29*P29 -> 39.001176
D30: 24 | E30: 13.798203 | F30: =$P$2*(E30/H15)+(1-$P$2)*(F29+G29) -> 9.6584567 | G30: =$P$3*(F30-F29)+(1-$P$3)*G29 -> 0 | H30: =$P$4*(E30/F30)+(1-$P$4)*H15 -> 1.4286136 | I30: =(F30+(G30))*H15 -> 13.798203 | J30: =E30-I30 -> 0 | K30: =ABS(J30) -> 0 | M30: =AVERAGE(E30:E44) -> 11.379156 | O30: =$V$2*D30+$V$3 -> 11.09902 | P30: =E30-O30 -> 2.6991829 | Q30: =P30*P30 -> 7.2855882
D31: 25 | E31: 29.557245 | F31: =$P$2*(E31/H16)+(1-$P$2)*(F30+G30) -> 46.994627 | G31: =$P$3*(F31-F30)+(1-$P$3)*G30 -> 0 | H31: =$P$4*(E31/F31)+(1-$P$4)*H16 -> 0.62894945 | I31: =(F31+(G31))*H16 -> 29.557245 | J31: =E31-I31 -> 0 | K31: =ABS(J31) -> 0 | M31: =AVERAGE(E31:E45) -> 11.725942 | O31: =$V$2*D31+$V$3 -> 11.09902 | P31: =E31-O31 -> 18.458225 | Q31: =P31*P31 -> 340.70607
D32: 26 | E32: 5.331885 | F32: =$P$2*(E32/H17)+(1-$P$2)*(F31+G31) -> 5.9170121 | G32: =$P$3*(F32-F31)+(1-$P$3)*G31 -> 0 | H32: =$P$4*(E32/F32)+(1-$P$4)*H17 -> 0.90111105 | I32: =(F32+(G32))*H17 -> 5.331885 | J32: =E32-I32 -> 0 | K32: =ABS(J32) -> 0 | M32: =AVERAGE(E32:E46) -> 9.8221257 | O32: =$V$2*D32+$V$3 -> 11.09902 | P32: =E32-O32 -> -5.7671351 | Q32: =P32*P32 -> 33.259848
C33: round4 | D33: 27 | E33: 17 | F33: =$P$2*(E33/H18)+(1-$P$2)*(F32+G32) -> 58.954997 | G33: =$P$3*(F33-F32)+(1-$P$3)*G32 -> 0 | H33: =$P$4*(E33/F33)+(1-$P$4)*H18 -> 0.28835554 | I33: =(F33+(G33))*H18 -> 17 | J33: =E33-I33 -> 0 | K33: =ABS(J33) -> 0 | M33: =AVERAGE(E33:E47) -> 11.533333 | O33: =$V$2*D33+$V$3 -> 11.09902 | P33: =E33-O33 -> 5.9009799 | Q33: =P33*P33 -> 34.821563
D34: 28 | E34: 8 | F34: =$P$2*(E34/H19)+(1-$P$2)*(F33+G33) -> 6.7257032 | G34: =$P$3*(F34-F33)+(1-$P$3)*G33 -> 0 | H34: =$P$4*(E34/F34)+(1-$P$4)*H19 -> 1.1894667 | I34: =(F34+(G34))*H19 -> 8 | J34: =E34-I34 -> 0 | K34: =ABS(J34) -> 0 | M34: =AVERAGE(E34:E48) -> 11.066667 | O34: =$V$2*D34+$V$3 -> 11.09902 | P34: =E34-O34 -> -3.0990201 | Q34: =P34*P34 -> 9.6039258
D35: 29 | E35: 11 | F35: =$P$2*(E35/H20)+(1-$P$2)*(F34+G34) -> 8.8457619 | G35: =$P$3*(F35-F34)+(1-$P$3)*G34 -> 0 | H35: =$P$4*(E35/F35)+(1-$P$4)*H20 -> 1.2435334 | I35: =(F35+(G35))*H20 -> 11 | J35: =E35-I35 -> 0 | K35: =ABS(J35) -> 0 | M35: =AVERAGE(E35:E49) -> 11.2 | O35: =$V$2*D35+$V$3 -> 11.09902 | P35: =E35-O35 -> -0.09902013 | Q35: =P35*P35 -> 0.0098049862
D36: 30 | E36: 1 | F36: =$P$2*(E36/H21)+(1-$P$2)*(F35+G35) -> 1.144063 | G36: =$P$3*(F36-F35)+(1-$P$3)*G35 -> 0 | H36: =$P$4*(E36/F36)+(1-$P$4)*H21 -> 0.87407777 | I36: =(F36+(G36))*H21 -> 1 | J36: =E36-I36 -> 0 | K36: =ABS(J36) -> 0 | M36: =AVERAGE(E36:E50) -> 11.2 | O36: =$V$2*D36+$V$3 -> 11.09902 | P36: =E36-O36 -> -10.09902 | Q36: =P36*P36 -> 101.99021
D37: 31 | E37: 10 | F37: =$P$2*(E37/H22)+(1-$P$2)*(F36+G36) -> 4.6960636 | G37: =$P$3*(F37-F36)+(1-$P$3)*G36 -> 0 | H37: =$P$4*(E37/F37)+(1-$P$4)*H22 -> 2.1294431 | I37: =(F37+(G37))*H22 -> 10 | J37: =E37-I37 -> 0 | K37: =ABS(J37) -> 0 | M37: =AVERAGE(E37:E51) -> 12 | O37: =$V$2*D37+$V$3 -> 11.09902 | P37: =E37-O37 -> -1.0990201 | Q37: =P37*P37 -> 1.2078452
D38: 32 | E38: 11 | F38: =$P$2*(E38/H23)+(1-$P$2)*(F37+G37) -> 53.22886 | G38: =$P$3*(F38-F37)+(1-$P$3)*G37 -> 0 | H38: =$P$4*(E38/F38)+(1-$P$4)*H23 -> 0.20665481 | I38: =(F38+(G38))*H23 -> 11 | J38: =E38-I38 -> 0 | K38: =ABS(J38) -> 0 | M38: =AVERAGE(E38:E52) -> 12 | O38: =$V$2*D38+$V$3 -> 11.09902 | P38: =E38-O38 -> -0.09902013 | Q38: =P38*P38 -> 0.0098049862
D39: 33 | E39: 1 | F39: =$P$2*(E39/H24)+(1-$P$2)*(F38+G38) -> 1.7666143 | G39: =$P$3*(F39-F38)+(1-$P$3)*G38 -> 0 | H39: =$P$4*(E39/F39)+(1-$P$4)*H24 -> 0.5660545 | I39: =(F39+(G39))*H24 -> 1 | J39: =E39-I39 -> -3.3306691e-15 | K39: =ABS(J39) -> 3.3306691e-15 | M39: =AVERAGE(E39:E53) -> 11.27 | O39: =$V$2*D39+$V$3 -> 11.09902 | P39: =E39-O39 -> -10.09902 | Q39: =P39*P39 -> 101.99021
D40: 34 | E40: 31 | F40: =$P$2*(E40/H25)+(1-$P$2)*(F39+G39) -> 30.805338 | G40: =$P$3*(F40-F39)+(1-$P$3)*G39 -> 0 | H40: =$P$4*(E40/F40)+(1-$P$4)*H25 -> 1.0063191 | I40: =(F40+(G40))*H25 -> 31 | J40: =E40-I40 -> 0 | K40: =ABS(J40) -> 0 | M40: =AVERAGE(E40:E54) -> 11.936667 | O40: =$V$2*D40+$V$3 -> 11.09902 | P40: =E40-O40 -> 19.90098 | Q40: =P40*P40 -> 396.049
D41: 35 | E41: 11 | F41: =$P$2*(E41/H26)+(1-$P$2)*(F40+G40) -> 11.231778 | G41: =$P$3*(F41-F40)+(1-$P$3)*G40 -> 0 | H41: =$P$4*(E41/F41)+(1-$P$4)*H26 -> 0.97936412 | I41: =(F41+(G41))*H26 -> 11 | J41: =E41-I41 -> 0 | K41: =ABS(J41) -> 0 | M41: =AVERAGE(E41:E55) -> 10.603333 | O41: =$V$2*D41+$V$3 -> 11.09902 | P41: =E41-O41 -> -0.09902013 | Q41: =P41*P41 -> 0.0098049862
...

Sheet orpet
O2: alpha | P2: 1 | U2: coefii dir | V2: 0.096161901
O3: bet | P3: 0.0021539948 | Q3: error2 | R3: =SUM(K21:K84) -> 11.418158 | U3: origine | V3: 113.36041
O4: gamma | P4: 1 | U4: sum | V4: =SUM(Q7:Q70) -> 157608.14
V5: =COUNT($P$2:$P$4) -> 3
D6: period | E6: Y | F6: level | G6: trend | H6: season | I6: forcast | J6: error | K6: abs error | L6: average regression | O6: y | P6: erro | Q6: error2
C7: round3 | D7: 1 | E7: 184.4336 | H7: =E7/$A$44 -> 1.6056218 | M7: =AVERAGE(E7:E21) -> 114.8674 | O7: =$V$2*D7+$V$3 -> 113.45658 | P7: =E7-O7 -> 70.977025 | Q7: =P7*P7 -> 5037.7381
D8: 2 | E8: 76.69328 | H8: =E8/$A$44 -> 0.66766796 | M8: =AVERAGE(E8:E22) -> 114.62979 | O8: =$V$2*D8+$V$3 -> 113.55274 | P8: =E8-O8 -> -36.859457 | Q8: =P8*P8 -> 1358.6196
D9: 3 | E9: 165.47472 | H9: =E9/$A$44 -> 1.4405717 | M9: =AVERAGE(E9:E23) -> 114.85024 | O9: =$V$2*D9+$V$3 -> 113.6489 | P9: =E9-O9 -> 51.825821 | Q9: =P9*P9 -> 2685.9157
D10: 4 | E10: 37.737354 | H10: =E10/$A$44 -> 0.32852972 | M10: =AVERAGE(E10:E24) -> 114.36932 | O10: =$V$2*D10+$V$3 -> 113.74506 | P10: =E10-O10 -> -76.007707 | Q10: =P10*P10 -> 5777.1715
D11: 5 | E11: 92.60278 | H11: =E11/$A$44 -> 0.80617114 | M11: =AVERAGE(E11:E25) -> 118.75205 | O11: =$V$2*D11+$V$3 -> 113.84122 | P11: =E11-O11 -> -21.238443 | Q11: =P11*P11 -> 451.07145
D12: 6 | E12: 107.47412 | H12: =E12/$A$44 -> 0.93563643 | M12: =AVERAGE(E12:E26) -> 117.10027 | O12: =$V$2*D12+$V$3 -> 113.93738 | P12: =E12-O12 -> -6.4632646 | Q12: =P12*P12 -> 41.77379
D13: 7 | E13: 70.16859 | H13: =E13/$A$44 -> 0.61086603 | M13: =AVERAGE(E13:E27) -> 116.09812 | O13: =$V$2*D13+$V$3 -> 114.03355 | P13: =E13-O13 -> -43.864957 | Q13: =P13*P13 -> 1924.1344
D14: 8 | E14: 166.77611 | H14: =E14/$A$44 -> 1.4519012 | M14: =AVERAGE(E14:E28) -> 119.61788 | O14: =$V$2*D14+$V$3 -> 114.12971 | P14: =E14-O14 -> 52.646402 | Q14: =P14*P14 -> 2771.6436
D15: 9 | E15: 159.91127 | H15: =E15/$A$44 -> 1.392138 | M15: =AVERAGE(E15:E29) -> 116.58087 | O15: =$V$2*D15+$V$3 -> 114.22587 | P15: =E15-O15 -> 45.6854 | Q15: =P15*P15 -> 2087.1557
D16: 10 | E16: 257.3913 | H16: =E16/$A$44 -> 2.240769 | M16: =AVERAGE(E16:E30) -> 111.67594 | O16: =$V$2*D16+$V$3 -> 114.32203 | P16: =E16-O16 -> 143.06927 | Q16: =P16*P16 -> 20468.815
D17: 11 | E17: 76.521736 | H17: =E17/$A$44 -> 0.66617455 | M17: =AVERAGE(E17:E31) -> 100.03977 | O17: =$V$2*D17+$V$3 -> 114.41819 | P17: =E17-O17 -> -37.896458 | Q17: =P17*P17 -> 1436.1415
D18: 12 | E18: 53.913044 | H18: =E18/$A$44 -> 0.46935028 | M18: =AVERAGE(E18:E32) -> 105.92669 | O18: =$V$2*D18+$V$3 -> 114.51436 | P18: =E18-O18 -> -60.601312 | Q18: =P18*P18 -> 3672.519
D19: 13 | E19: 110.43478 | H19: =E19/$A$44 -> 0.96141105 | M19: =AVERAGE(E19:E33) -> 114.53249 | O19: =$V$2*D19+$V$3 -> 114.61052 | P19: =E19-O19 -> -4.1757339 | Q19: =P19*P19 -> 17.436754
D20: 14 | E20: 84.347824 | H20: =E20/$A$44 -> 0.73430605 | M20: =AVERAGE(E20:E34) -> 112.57017 | O20: =$V$2*D20+$V$3 -> 114.70668 | P20: =E20-O20 -> -30.358856 | Q20: =P20*P20 -> 921.66013
D21: 15 | E21: 79.13043 | F21: =V3 -> 113.36041 | G21: =V2+0.1 -> 0.1961619 | H21: =E21/$A$44 -> 0.68888503 | M21: =AVERAGE(E21:E35) -> 117.61365 | O21: =$V$2*D21+$V$3 -> 114.80284 | P21: =E21-O21 -> -35.672412 | Q21: =P21*P21 -> 1272.521
D22: 16 | E22: 180.86957 | F22: =$P$2*(E22/H7)+(1-$P$2)*(F21+G21) -> 112.64768 | G22: =$P$3*(F22-F21)+(1-$P$3)*G21 -> 0.19420414 | H22: =$P$4*(E22/F22)+(1-$P$4)*H7 -> 1.6056218 | I22: =(F22+(G22))*H7 -> 181.18139 | J22: =E22-I22 -> -0.31181841 | K22: =ABS(J22) -> 0.31181841 | M22: =AVERAGE(E22:E36) -> 115.13829 | O22: =$V$2*D22+$V$3 -> 114.899 | P22: =E22-O22 -> 65.970566 | Q22: =P22*P22 -> 4352.1156
D23: 17 | E23: 80 | F23: =$P$2*(E23/H8)+(1-$P$2)*(F22+G22) -> 119.82004 | G23: =$P$3*(F23-F22)+(1-$P$3)*G22 -> 0.20923505 | H23: =$P$4*(E23/F23)+(1-$P$4)*H8 -> 0.66766796 | I23: =(F23+(G23))*H8 -> 80.1397 | J23: =E23-I23 -> -0.13969954 | K23: =ABS(J23) -> 0.13969954 | M23: =AVERAGE(E23:E37) -> 108.88032 | O23: =$V$2*D23+$V$3 -> 114.99517 | P23: =E23-O23 -> -34.995166 | Q23: =P23*P23 -> 1224.6616
D24: 18 | E24: 158.26086 | F24: =$P$2*(E24/H9)+(1-$P$2)*(F23+G23) -> 109.85976 | G24: =$P$3*(F24-F23)+(1-$P$3)*G23 -> 0.18732997 | H24: =$P$4*(E24/F24)+(1-$P$4)*H9 -> 1.4405717 | I24: =(F24+(G24))*H9 -> 158.53072 | J24: =E24-I24 -> -0.26986226 | K24: =ABS(J24) -> 0.26986226 | M24: =AVERAGE(E24:E38) -> 110.81365 | O24: =$V$2*D24+$V$3 -> 115.09133 | P24: =E24-O24 -> 43.169533 | Q24: =P24*P24 -> 1863.6085
D25: 19 | E25: 103.47826 | F25: =$P$2*(E25/H10)+(1-$P$2)*(F24+G24) -> 314.97383 | G25: =$P$3*(F25-F24)+(1-$P$3)*G24 -> 0.6287411 | H25: =$P$4*(E25/F25)+(1-$P$4)*H10 -> 0.32852972 | I25: =(F25+(G25))*H10 -> 103.68482 | J25: =E25-I25 -> -0.20656014 | K25: =ABS(J25) -> 0.20656014 | M25: =AVERAGE(E25:E39) -> 105.46293 | O25: =$V$2*D25+$V$3 -> 115.18749 | P25: =E25-O25 -> -11.709225 | Q25: =P25*P25 -> 137.10596
D26: 20 | E26: 67.82609 | F26: =$P$2*(E26/H11)+(1-$P$2)*(F25+G25) -> 84.133612 | G26: =$P$3*(F26-F25)+(1-$P$3)*G25 -> 0.13015817 | H26: =$P$4*(E26/F26)+(1-$P$4)*H11 -> 0.80617114 | I26: =(F26+(G26))*H11 -> 67.93102 | J26: =E26-I26 -> -0.10492976 | K26: =ABS(J26) -> 0.10492976 | M26: =AVERAGE(E26:E40) -> 109.63104 | O26: =$V$2*D26+$V$3 -> 115.28365 | P26: =E26-O26 -> -47.457561 | Q26: =P26*P26 -> 2252.2201
D27: 21 | E27: 92.441864 | F27: =$P$2*(E27/H12)+(1-$P$2)*(F26+G26) -> 98.801053 | G27: =$P$3*(F27-F26)+(1-$P$3)*G26 -> 0.1614714 | H27: =$P$4*(E27/F27)+(1-$P$4)*H12 -> 0.93563643 | I27: =(F27+(G27))*H12 -> 92.592943 | J27: =E27-I27 -> -0.15107853 | K27: =ABS(J27) -> 0.15107853 | M27: =AVERAGE(E27:E41) -> 115.64264 | O27: =$V$2*D27+$V$3 -> 115.37981 | P27: =E27-O27 -> -22.937949 | Q27: =P27*P27 -> 526.14951
D28: 22 | E28: 122.96512 | F28: =$P$2*(E28/H13)+(1-$P$2)*(F27+G27) -> 201.29638 | G28: =$P$3*(F28-F27)+(1-$P$3)*G27 -> 0.381898 | H28: =$P$4*(E28/F28)+(1-$P$4)*H13 -> 0.61086603 | I28: =(F28+(G28))*H13 -> 123.19841 | J28: =E28-I28 -> -0.23328851 | K28: =ABS(J28) -> 0.23328851 | M28: =AVERAGE(E28:E42) -> 126.47985 | O28: =$V$2*D28+$V$3 -> 115.47598 | P28: =E28-O28 -> 7.4891449 | Q28: =P28*P28 -> 56.087292
D29: 23 | E29: 121.22093 | F29: =$P$2*(E29/H14)+(1-$P$2)*(F28+G28) -> 83.49117 | G29: =$P$3*(F29-F28)+(1-$P$3)*G28 -> 0.12732358 | H29: =$P$4*(E29/F29)+(1-$P$4)*H14 -> 1.4519012 | I29: =(F29+(G29))*H14 -> 121.40579 | J29: =E29-I29 -> -0.18486126 | K29: =ABS(J29) -> 0.18486126 | M29: =AVERAGE(E29:E43) -> 123.8155 | O29: =$V$2*D29+$V$3 -> 115.57214 | P29: =E29-O29 -> 5.648793 | Q29: =P29*P29 -> 31.908863
D30: 24 | E30: 86.33721 | F30: =$P$2*(E30/H15)+(1-$P$2)*(F29+G29) -> 62.017708 | G30: =$P$3*(F30-F29)+(1-$P$3)*G29 -> 0.0807956 | H30: =$P$4*(E30/F30)+(1-$P$4)*H15 -> 1.392138 | I30: =(F30+(G30))*H15 -> 86.449689 | J30: =E30-I30 -> -0.11247863 | K30: =ABS(J30) -> 0.11247863 | M30: =AVERAGE(E30:E44) -> 119.33411 | O30: =$V$2*D30+$V$3 -> 115.6683 | P30: =E30-O30 -> -29.331089 | Q30: =P30*P30 -> 860.31277
D31: 25 | E31: 82.84884 | F31: =$P$2*(E31/H16)+(1-$P$2)*(F30+G30) -> 36.973396 | G31: =$P$3*(F31-F30)+(1-$P$3)*G30 -> 0.026676248 | H31: =$P$4*(E31/F31)+(1-$P$4)*H16 -> 2.240769 | I31: =(F31+(G31))*H16 -> 82.908615 | J31: =E31-I31 -> -0.059775309 | K31: =ABS(J31) -> 0.059775309 | M31: =AVERAGE(E31:E45) -> 120.51163 | O31: =$V$2*D31+$V$3 -> 115.76446 | P31: =E31-O31 -> -32.915621 | Q31: =P31*P31 -> 1083.4381
D32: 26 | E32: 164.82558 | F32: =$P$2*(E32/H17)+(1-$P$2)*(F31+G31) -> 247.42101 | G32: =$P$3*(F32-F31)+(1-$P$3)*G31 -> 0.47992186 | H32: =$P$4*(E32/F32)+(1-$P$4)*H17 -> 0.66617455 | I32: =(F32+(G32))*H17 -> 165.14529 | J32: =E32-I32 -> -0.31971173 | K32: =ABS(J32) -> 0.31971173 | M32: =AVERAGE(E32:E46) -> 120.25504 | O32: =$V$2*D32+$V$3 -> 115.86062 | P32: =E32-O32 -> 48.964957 | Q32: =P32*P32 -> 2397.567
C33: round4 | D33: 27 | E33: 183 | F33: =$P$2*(E33/H18)+(1-$P$2)*(F32+G32) -> 389.9007 | G33: =$P$3*(F33-F32)+(1-$P$3)*G32 -> 0.78578862 | H33: =$P$4*(E33/F33)+(1-$P$4)*H18 -> 0.46935028 | I33: =(F33+(G33))*H18 -> 183.36881 | J33: =E33-I33 -> -0.36881011 | K33: =ABS(J33) -> 0.36881011 | M33: =AVERAGE(E33:E47) -> 114.26667 | O33: =$V$2*D33+$V$3 -> 115.95678 | P33: =E33-O33 -> 67.043215 | Q33: =P33*P33 -> 4494.7927
D34: 28 | E34: 81 | F34: =$P$2*(E34/H19)+(1-$P$2)*(F33+G33) -> 84.251164 | G34: =$P$3*(F34-F33)+(1-$P$3)*G33 -> 0.12572852 | H34: =$P$4*(E34/F34)+(1-$P$4)*H19 -> 0.96141105 | I34: =(F34+(G34))*H19 -> 81.120877 | J34: =E34-I34 -> -0.12087679 | K34: =ABS(J34) -> 0.12087679 | M34: =AVERAGE(E34:E48) -> 113.6 | O34: =$V$2*D34+$V$3 -> 116.05295 | P34: =E34-O34 -> -35.052946 | Q34: =P34*P34 -> 1228.7091
D35: 29 | E35: 160 | F35: =$P$2*(E35/H20)+(1-$P$2)*(F34+G34) -> 217.8928 | G35: =$P$3*(F35-F34)+(1-$P$3)*G34 -> 0.41332109 | H35: =$P$4*(E35/F35)+(1-$P$4)*H20 -> 0.73430605 | I35: =(F35+(G35))*H20 -> 160.3035 | J35: =E35-I35 -> -0.30350418 | K35: =ABS(J35) -> 0.30350418 | M35: =AVERAGE(E35:E49) -> 113.06667 | O35: =$V$2*D35+$V$3 -> 116.14911 | P35: =E35-O35 -> 43.850892 | Q35: =P35*P35 -> 1922.9007
D36: 30 | E36: 42 | F36: =$P$2*(E36/H21)+(1-$P$2)*(F35+G35) -> 60.968083 | G36: =$P$3*(F36-F35)+(1-$P$3)*G35 -> 0.074415775 | H36: =$P$4*(E36/F36)+(1-$P$4)*H21 -> 0.68888503 | I36: =(F36+(G36))*H21 -> 42.051264 | J36: =E36-I36 -> -0.051263914 | K36: =ABS(J36) -> 0.051263914 | M36: =AVERAGE(E36:E50) -> 112.53333 | O36: =$V$2*D36+$V$3 -> 116.24527 | P36: =E36-O36 -> -74.24527 | Q36: =P36*P36 -> 5512.3602
D37: 31 | E37: 87 | F37: =$P$2*(E37/H22)+(1-$P$2)*(F36+G36) -> 54.184614 | G37: =$P$3*(F37-F36)+(1-$P$3)*G36 -> 0.059643927 | H37: =$P$4*(E37/F37)+(1-$P$4)*H22 -> 1.6056218 | I37: =(F37+(G37))*H22 -> 87.095766 | J37: =E37-I37 -> -0.095765592 | K37: =ABS(J37) -> 0.095765592 | M37: =AVERAGE(E37:E51) -> 115.73333 | O37: =$V$2*D37+$V$3 -> 116.34143 | P37: =E37-O37 -> -29.341432 | Q37: =P37*P37 -> 860.91964
D38: 32 | E38: 109 | F38: =$P$2*(E38/H23)+(1-$P$2)*(F37+G37) -> 163.2548 | G38: =$P$3*(F38-F37)+(1-$P$3)*G37 -> 0.29445207 | H38: =$P$4*(E38/F38)+(1-$P$4)*H23 -> 0.66766796 | I38: =(F38+(G38))*H23 -> 109.1966 | J38: =E38-I38 -> -0.19659621 | K38: =ABS(J38) -> 0.19659621 | M38: =AVERAGE(E38:E52) -> 114.13333 | O38: =$V$2*D38+$V$3 -> 116.43759 | P38: =E38-O38 -> -7.4375941 | Q38: =P38*P38 -> 55.317805
D39: 33 | E39: 78 | F39: =$P$2*(E39/H24)+(1-$P$2)*(F38+G38) -> 54.14517 | G39: =$P$3*(F39-F38)+(1-$P$3)*G38 -> 0.058796244 | H39: =$P$4*(E39/F39)+(1-$P$4)*H24 -> 1.4405717 | I39: =(F39+(G39))*H24 -> 78.0847 | J39: =E39-I39 -> -0.084700205 | K39: =ABS(J39) -> 0.084700205 | M39: =AVERAGE(E39:E53) -> 113.73333 | O39: =$V$2*D39+$V$3 -> 116.53376 | P39: =E39-O39 -> -38.533756 | Q39: =P39*P39 -> 1484.8503
D40: 34 | E40: 166 | F40: =$P$2*(E40/H25)+(1-$P$2)*(F39+G39) -> 505.28152 | G40: =$P$3*(F40-F39)+(1-$P$3)*G39 -> 1.030415 | H40: =$P$4*(E40/F40)+(1-$P$4)*H25 -> 0.32852972 | I40: =(F40+(G40))*H25 -> 166.33852 | J40: =E40-I40 -> -0.33852195 | K40: =ABS(J40) -> 0.33852195 | M40: =AVERAGE(E40:E54) -> 117.46667 | O40: =$V$2*D40+$V$3 -> 116.62992 | P40: =E40-O40 -> 49.370082 | Q40: =P40*P40 -> 2437.405
D41: 35 | E41: 158 | F41: =$P$2*(E41/H26)+(1-$P$2)*(F40+G40) -> 195.98816 | G41: =$P$3*(F41-F40)+(1-$P$3)*G40 -> 0.36197916 | H41: =$P$4*(E41/F41)+(1-$P$4)*H26 -> 0.80617114 | I41: =(F41+(G41))*H26 -> 158.29182 | J41: =E41-I41 -> -0.29181715 | K41: =ABS(J41) -> 0.29181715 | M41: =AVERAGE(E41:E55) -> 115.13333 | O41: =$V$2*D41+$V$3 -> 116.72608 | P41: =E41-O41 -> 41.27392 | Q41: =P41*P41 -> 1703.5365
...

Sheet ormangopet
O2: alpha | P2: 1 | U2: coefii dir | V2: 0
O3: bet | P3: 0 | Q3: error2 | R3: =SUM(K21:K84) -> 8.8817842e-15 | U3: origine | V3: 52.401031
O4: gamma | P4: 1 | U4: sum | V4: =SUM(Q7:Q70) -> 54479.129
V5: =COUNT($P$2:$P$4) -> 3
D6: period | E6: Y | F6: level | G6: trend | H6: season | I6: forcast | J6: error | K6: abs error | L6: average regression | O6: y | P6: erro | Q6: error2
C7: round3 | D7: 1 | E7: 58.028984 | H7: =E7/$A$44 -> 1.067178 | M7: =AVERAGE(E7:E21) -> 54.376104 | O7: =$V$2*D7+$V$3 -> 52.401031 | P7: =E7-O7 -> 5.6279529 | Q7: =P7*P7 -> 31.673854
D8: 2 | E8: 26.376812 | H8: =E8/$A$44 -> 0.48508095 | M8: =AVERAGE(E8:E22) -> 51.864094 | O8: =$V$2*D8+$V$3 -> 52.401031 | P8: =E8-O8 -> -26.024219 | Q8: =P8*P8 -> 677.25998
D9: 3 | E9: 45.855072 | H9: =E9/$A$44 -> 0.84329455 | M9: =AVERAGE(E9:E23) -> 52.194787 | O9: =$V$2*D9+$V$3 -> 52.401031 | P9: =E9-O9 -> -6.5459591 | Q9: =P9*P9 -> 42.84958
D10: 4 | E10: 41.391304 | H10: =E10/$A$44 -> 0.76120393 | M10: =AVERAGE(E10:E24) -> 57.657162 | O10: =$V$2*D10+$V$3 -> 52.401031 | P10: =E10-O10 -> -11.009727 | Q10: =P10*P10 -> 121.21409
D11: 5 | E11: 69.797104 | H11: =E11/$A$44 -> 1.2835988 | M11: =AVERAGE(E11:E25) -> 57.448129 | O11: =$V$2*D11+$V$3 -> 52.401031 | P11: =E11-O11 -> 17.396073 | Q11: =P11*P11 -> 302.62335
D12: 6 | E12: 85.62319 | H12: =E12/$A$44 -> 1.5746474 | M12: =AVERAGE(E12:E26) -> 55.453904 | O12: =$V$2*D12+$V$3 -> 52.401031 | P12: =E12-O12 -> 33.222159 | Q12: =P12*P12 -> 1103.7118
D13: 7 | E13: 87.246376 | H13: =E13/$A$44 -> 1.6044985 | M13: =AVERAGE(E13:E27) -> 53.147052 | O13: =$V$2*D13+$V$3 -> 52.401031 | P13: =E13-O13 -> 34.845345 | Q13: =P13*P13 -> 1214.1981
D14: 8 | E14: 34.086956 | H14: =E14/$A$44 -> 0.62687382 | M14: =AVERAGE(E14:E28) -> 50.323824 | O14: =$V$2*D14+$V$3 -> 52.401031 | P14: =E14-O14 -> -18.314075 | Q14: =P14*P14 -> 335.40535
D15: 9 | E15: 38.95652 | H15: =E15/$A$44 -> 0.71642721 | M15: =AVERAGE(E15:E29) -> 49.711224 | O15: =$V$2*D15+$V$3 -> 52.401031 | P15: =E15-O15 -> -13.444511 | Q15: =P15*P15 -> 180.75488
D16: 10 | E16: 51.942028 | H16: =E16/$A$44 -> 0.9552363 | M16: =AVERAGE(E16:E30) -> 51.903238 | O16: =$V$2*D16+$V$3 -> 52.401031 | P16: =E16-O16 -> -0.45900309 | Q16: =P16*P16 -> 0.21068384
D17: 11 | E17: 116.39535 | H17: =E17/$A$44 -> 2.1405607 | M17: =AVERAGE(E17:E31) -> 52.005062 | O17: =$V$2*D17+$V$3 -> 52.401031 | P17: =E17-O17 -> 63.994319 | Q17: =P17*P17 -> 4095.2729
D18: 12 | E18: 40.697674 | H18: =E18/$A$44 -> 0.74844778 | M18: =AVERAGE(E18:E32) -> 46.531086 | O18: =$V$2*D18+$V$3 -> 52.401031 | P18: =E18-O18 -> -11.703357 | Q18: =P18*P18 -> 136.96857
D19: 13 | E19: 45.17442 | H19: =E19/$A$44 -> 0.83077707 | M19: =AVERAGE(E19:E33) -> 51.351241 | O19: =$V$2*D19+$V$3 -> 52.401031 | P19: =E19-O19 -> -7.2266111 | Q19: =P19*P19 -> 52.223908
D20: 14 | E20: 25.232557 | H20: =E20/$A$44 -> 0.46403761 | M20: =AVERAGE(E20:E34) -> 50.339613 | O20: =$V$2*D20+$V$3 -> 52.401031 | P20: =E20-O20 -> -27.168474 | Q20: =P20*P20 -> 738.12598
D21: 15 | E21: 48.837208 | F21: =V3 -> 52.401031 | G21: =V2 -> 0 | H21: =E21/$A$44 -> 0.89813732 | M21: =AVERAGE(E21:E35) -> 54.92411 | O21: =$V$2*D21+$V$3 -> 52.401031 | P21: =E21-O21 -> -3.5638231 | Q21: =P21*P21 -> 12.700835
D22: 16 | E22: 20.348837 | F22: =$P$2*(E22/H7)+(1-$P$2)*(F21+G21) -> 19.067893 | G22: =$P$3*(F22-F21)+(1-$P$3)*G21 -> 0 | H22: =$P$4*(E22/F22)+(1-$P$4)*H7 -> 1.067178 | I22: =(F22+(G22))*H7 -> 20.348837 | J22: =E22-I22 -> 0 | K22: =ABS(J22) -> 0 | M22: =AVERAGE(E22:E36) -> 53.268296 | O22: =$V$2*D22+$V$3 -> 52.401031 | P22: =E22-O22 -> -32.052194 | Q22: =P22*P22 -> 1027.3431
D23: 17 | E23: 31.33721 | F23: =$P$2*(E23/H8)+(1-$P$2)*(F22+G22) -> 64.602022 | G23: =$P$3*(F23-F22)+(1-$P$3)*G22 -> 0 | H23: =$P$4*(E23/F23)+(1-$P$4)*H8 -> 0.48508095 | I23: =(F23+(G23))*H8 -> 31.33721 | J23: =E23-I23 -> 0 | K23: =ABS(J23) -> 0 | M23: =AVERAGE(E23:E37) -> 53.64504 | O23: =$V$2*D23+$V$3 -> 52.401031 | P23: =E23-O23 -> -21.063821 | Q23: =P23*P23 -> 443.68456
D24: 18 | E24: 127.79069 | F24: =$P$2*(E24/H9)+(1-$P$2)*(F23+G23) -> 151.53744 | G24: =$P$3*(F24-F23)+(1-$P$3)*G23 -> 0 | H24: =$P$4*(E24/F24)+(1-$P$4)*H9 -> 0.84329455 | I24: =(F24+(G24))*H9 -> 127.79069 | J24: =E24-I24 -> 0 | K24: =ABS(J24) -> 0 | M24: =AVERAGE(E24:E38) -> 55.155893 | O24: =$V$2*D24+$V$3 -> 52.401031 | P24: =E24-O24 -> 75.389664 | Q24: =P24*P24 -> 5683.6014
D25: 19 | E25: 38.255814 | F25: =$P$2*(E25/H10)+(1-$P$2)*(F24+G24) -> 50.256984 | G25: =$P$3*(F25-F24)+(1-$P$3)*G24 -> 0 | H25: =$P$4*(E25/F25)+(1-$P$4)*H10 -> 0.76120393 | I25: =(F25+(G25))*H10 -> 38.255814 | J25: =E25-I25 -> 0 | K25: =ABS(J25) -> 0 | M25: =AVERAGE(E25:E39) -> 50.30318 | O25: =$V$2*D25+$V$3 -> 52.401031 | P25: =E25-O25 -> -14.145217 | Q25: =P25*P25 -> 200.08717
D26: 20 | E26: 39.88372 | F26: =$P$2*(E26/H11)+(1-$P$2)*(F25+G25) -> 31.071795 | G26: =$P$3*(F26-F25)+(1-$P$3)*G25 -> 0 | H26: =$P$4*(E26/F26)+(1-$P$4)*H11 -> 1.2835988 | I26: =(F26+(G26))*H11 -> 39.88372 | J26: =E26-I26 -> 0 | K26: =ABS(J26) -> 0 | M26: =AVERAGE(E26:E40) -> 50.019459 | O26: =$V$2*D26+$V$3 -> 52.401031 | P26: =E26-O26 -> -12.517311 | Q26: =P26*P26 -> 156.68308
D27: 21 | E27: 51.02041 | F27: =$P$2*(E27/H12)+(1-$P$2)*(F26+G26) -> 32.401165 | G27: =$P$3*(F27-F26)+(1-$P$3)*G26 -> 0 | H27: =$P$4*(E27/F27)+(1-$P$4)*H12 -> 1.5746474 | I27: =(F27+(G27))*H12 -> 51.02041 | J27: =E27-I27 -> 0 | K27: =ABS(J27) -> 0 | M27: =AVERAGE(E27:E41) -> 52.693877 | O27: =$V$2*D27+$V$3 -> 52.401031 | P27: =E27-O27 -> -1.3806211 | Q27: =P27*P27 -> 1.9061146
D28: 22 | E28: 44.89796 | F28: =$P$2*(E28/H13)+(1-$P$2)*(F27+G27) -> 27.982551 | G28: =$P$3*(F28-F27)+(1-$P$3)*G27 -> 0 | H28: =$P$4*(E28/F28)+(1-$P$4)*H13 -> 1.6044985 | I28: =(F28+(G28))*H13 -> 44.89796 | J28: =E28-I28 -> 0 | K28: =ABS(J28) -> 0 | M28: =AVERAGE(E28:E42) -> 55.092517 | O28: =$V$2*D28+$V$3 -> 52.401031 | P28: =E28-O28 -> -7.5030711 | Q28: =P28*P28 -> 56.296076
D29: 23 | E29: 24.897959 | F29: =$P$2*(E29/H14)+(1-$P$2)*(F28+G28) -> 39.717656 | G29: =$P$3*(F29-F28)+(1-$P$3)*G28 -> 0 | H29: =$P$4*(E29/F29)+(1-$P$4)*H14 -> 0.62687382 | I29: =(F29+(G29))*H14 -> 24.897959 | J29: =E29-I29 -> 0 | K29: =ABS(J29) -> 0 | M29: =AVERAGE(E29:E43) -> 54.165986 | O29: =$V$2*D29+$V$3 -> 52.401031 | P29: =E29-O29 -> -27.503072 | Q29: =P29*P29 -> 756.41897
D30: 24 | E30: 71.83673 | F30: =$P$2*(E30/H15)+(1-$P$2)*(F29+G29) -> 100.2708 | G30: =$P$3*(F30-F29)+(1-$P$3)*G29 -> 0 | H30: =$P$4*(E30/F30)+(1-$P$4)*H15 -> 0.71642721 | I30: =(F30+(G30))*H15 -> 71.83673 | J30: =E30-I30 -> 0 | K30: =ABS(J30) -> 0 | M30: =AVERAGE(E30:E44) -> 54.039455 | O30: =$V$2*D30+$V$3 -> 52.401031 | P30: =E30-O30 -> 19.435699 | Q30: =P30*P30 -> 377.74639
D31: 25 | E31: 53.469387 | F31: =$P$2*(E31/H16)+(1-$P$2)*(F30+G30) -> 55.975037 | G31: =$P$3*(F31-F30)+(1-$P$3)*G30 -> 0 | H31: =$P$4*(E31/F31)+(1-$P$4)*H16 -> 0.9552363 | I31: =(F31+(G31))*H16 -> 53.469387 | J31: =E31-I31 -> 0 | K31: =ABS(J31) -> 0 | M31: =AVERAGE(E31:E45) -> 49.783673 | O31: =$V$2*D31+$V$3 -> 52.401031 | P31: =E31-O31 -> 1.0683559 | Q31: =P31*P31 -> 1.1413843
D32: 26 | E32: 34.285713 | F32: =$P$2*(E32/H17)+(1-$P$2)*(F31+G31) -> 16.017165 | G32: =$P$3*(F32-F31)+(1-$P$3)*G31 -> 0 | H32: =$P$4*(E32/F32)+(1-$P$4)*H17 -> 2.1405607 | I32: =(F32+(G32))*H17 -> 34.285713 | J32: =E32-I32 -> 0 | K32: =ABS(J32) -> 0 | M32: =AVERAGE(E32:E46) -> 52.485714 | O32: =$V$2*D32+$V$3 -> 52.401031 | P32: =E32-O32 -> -18.115318 | Q32: =P32*P32 -> 328.16475
C33: round4 | D33: 27 | E33: 113 | F33: =$P$2*(E33/H18)+(1-$P$2)*(F32+G32) -> 150.97914 | G33: =$P$3*(F33-F32)+(1-$P$3)*G32 -> 0 | H33: =$P$4*(E33/F33)+(1-$P$4)*H18 -> 0.74844778 | I33: =(F33+(G33))*H18 -> 113 | J33: =E33-I33 -> 0 | K33: =ABS(J33) -> 0 | M33: =AVERAGE(E33:E47) -> 52.4 | O33: =$V$2*D33+$V$3 -> 52.401031 | P33: =E33-O33 -> 60.598969 | Q33: =P33*P33 -> 3672.235
D34: 28 | E34: 30 | F34: =$P$2*(E34/H19)+(1-$P$2)*(F33+G33) -> 36.11077 | G34: =$P$3*(F34-F33)+(1-$P$3)*G33 -> 0 | H34: =$P$4*(E34/F34)+(1-$P$4)*H19 -> 0.83077707 | I34: =(F34+(G34))*H19 -> 30 | J34: =E34-I34 -> 0 | K34: =ABS(J34) -> 0 | M34: =AVERAGE(E34:E48) -> 48.066667 | O34: =$V$2*D34+$V$3 -> 52.401031 | P34: =E34-O34 -> -22.401031 | Q34: =P34*P34 -> 501.80619
D35: 29 | E35: 94 | F35: =$P$2*(E35/H20)+(1-$P$2)*(F34+G34) -> 202.56979 | G35: =$P$3*(F35-F34)+(1-$P$3)*G34 -> 0 | H35: =$P$4*(E35/F35)+(1-$P$4)*H20 -> 0.46403761 | I35: =(F35+(G35))*H20 -> 94 | J35: =E35-I35 -> 0 | K35: =ABS(J35) -> 0 | M35: =AVERAGE(E35:E49) -> 52.866667 | O35: =$V$2*D35+$V$3 -> 52.401031 | P35: =E35-O35 -> 41.598969 | Q35: =P35*P35 -> 1730.4742
D36: 30 | E36: 24 | F36: =$P$2*(E36/H21)+(1-$P$2)*(F35+G35) -> 26.721972 | G36: =$P$3*(F36-F35)+(1-$P$3)*G35 -> 0 | H36: =$P$4*(E36/F36)+(1-$P$4)*H21 -> 0.89813732 | I36: =(F36+(G36))*H21 -> 24 | J36: =E36-I36 -> 0 | K36: =ABS(J36) -> 0 | M36: =AVERAGE(E36:E50) -> 49.6 | O36: =$V$2*D36+$V$3 -> 52.401031 | P36: =E36-O36 -> -28.401031 | Q36: =P36*P36 -> 806.61857
D37: 31 | E37: 26 | F37: =$P$2*(E37/H22)+(1-$P$2)*(F36+G36) -> 24.36332 | G37: =$P$3*(F37-F36)+(1-$P$3)*G36 -> 0 | H37: =$P$4*(E37/F37)+(1-$P$4)*H22 -> 1.067178 | I37: =(F37+(G37))*H22 -> 26 | J37: =E37-I37 -> 0 | K37: =ABS(J37) -> 0 | M37: =AVERAGE(E37:E51) -> 49.333333 | O37: =$V$2*D37+$V$3 -> 52.401031 | P37: =E37-O37 -> -26.401031 | Q37: =P37*P37 -> 697.01444
D38: 32 | E38: 54 | F38: =$P$2*(E38/H23)+(1-$P$2)*(F37+G37) -> 111.32163 | G38: =$P$3*(F38-F37)+(1-$P$3)*G37 -> 0 | H38: =$P$4*(E38/F38)+(1-$P$4)*H23 -> 0.48508095 | I38: =(F38+(G38))*H23 -> 54 | J38: =E38-I38 -> 0 | K38: =ABS(J38) -> 0 | M38: =AVERAGE(E38:E52) -> 49.933333 | O38: =$V$2*D38+$V$3 -> 52.401031 | P38: =E38-O38 -> 1.5989689 | Q38: =P38*P38 -> 2.5567016
D39: 33 | E39: 55 | F39: =$P$2*(E39/H24)+(1-$P$2)*(F38+G38) -> 65.22039 | G39: =$P$3*(F39-F38)+(1-$P$3)*G38 -> 0 | H39: =$P$4*(E39/F39)+(1-$P$4)*H24 -> 0.84329455 | I39: =(F39+(G39))*H24 -> 55 | J39: =E39-I39 -> 0 | K39: =ABS(J39) -> 0 | M39: =AVERAGE(E39:E53) -> 49.066667 | O39: =$V$2*D39+$V$3 -> 52.401031 | P39: =E39-O39 -> 2.5989689 | Q39: =P39*P39 -> 6.7546394
D40: 34 | E40: 34 | F40: =$P$2*(E40/H25)+(1-$P$2)*(F39+G39) -> 44.666086 | G40: =$P$3*(F40-F39)+(1-$P$3)*G39 -> 0 | H40: =$P$4*(E40/F40)+(1-$P$4)*H25 -> 0.76120393 | I40: =(F40+(G40))*H25 -> 34 | J40: =E40-I40 -> 0 | K40: =ABS(J40) -> 0 | M40: =AVERAGE(E40:E54) -> 46.866667 | O40: =$V$2*D40+$V$3 -> 52.401031 | P40: =E40-O40 -> -18.401031 | Q40: =P40*P40 -> 338.59795
D41: 35 | E41: 80 | F41: =$P$2*(E41/H26)+(1-$P$2)*(F40+G40) -> 62.324768 | G41: =$P$3*(F41-F40)+(1-$P$3)*G40 -> 0 | H41: =$P$4*(E41/F41)+(1-$P$4)*H26 -> 1.2835988 | I41: =(F41+(G41))*H26 -> 80 | J41: =E41-I41 -> 0 | K41: =ABS(J41) -> 0 | M41: =AVERAGE(E41:E55) -> 48.8 | O41: =$V$2*D41+$V$3 -> 52.401031 | P41: =E41-O41 -> 27.598969 | Q41: =P41*P41 -> 761.70308
...

Sheet cpowpet
O2: alpha | P2: 1 | U2: coefii dir | V2: 0.043118678
O3: bet | P3: 0.002600114 | Q3: error2 | R3: =SUM(K21:K84) -> 2.6875999 | U3: origine | V3: 17.741247
O4: gamma | P4: 1 | U4: sum | V4: =SUM(Q7:Q70) -> 10023.196
V5: =COUNT($P$2:$P$4) -> 3
D6: period | E6: Y | F6: level | G6: trend | H6: season | I6: forcast | J6: error | K6: abs error | L6: average regression | O6: y | P6: erro | Q6: error2
C7: round3 | D7: 1 | E7: 19.011627 | H7: =E7/$A$44 -> 1.0943775 | M7: =AVERAGE(E7:E21) -> 17.372093 | O7: =$V$2*D7+$V$3 -> 17.784365 | P7: =E7-O7 -> 1.2272615 | Q7: =P7*P7 -> 1.5061709
D8: 2 | E8: 35.23256 | H8: =E8/$A$44 -> 2.0281126 | M8: =AVERAGE(E8:E22) -> 16.151163 | O8: =$V$2*D8+$V$3 -> 17.827484 | P8: =E8-O8 -> 17.405076 | Q8: =P8*P8 -> 302.93667
D9: 3 | E9: 29.476744 | H9: =E9/$A$44 -> 1.6967872 | M9: =AVERAGE(E9:E23) -> 16.162791 | O9: =$V$2*D9+$V$3 -> 17.870603 | P9: =E9-O9 -> 11.606141 | Q9: =P9*P9 -> 134.70251
D10: 4 | E10: 6.8023257 | H10: =E10/$A$44 -> 0.39156628 | M10: =AVERAGE(E10:E24) -> 15.569767 | O10: =$V$2*D10+$V$3 -> 17.913721 | P10: =E10-O10 -> -11.111396 | Q10: =P10*P10 -> 123.46312
D11: 5 | E11: 10.639535 | H11: =E11/$A$44 -> 0.61244981 | M11: =AVERAGE(E11:E25) -> 16.55814 | O11: =$V$2*D11+$V$3 -> 17.95684 | P11: =E11-O11 -> -7.3173052 | Q11: =P11*P11 -> 53.542955
D12: 6 | E12: 11.16279 | H12: =E12/$A$44 -> 0.64257025 | M12: =AVERAGE(E12:E26) -> 18.593023 | O12: =$V$2*D12+$V$3 -> 17.999959 | P12: =E12-O12 -> -6.8371689 | Q12: =P12*P12 -> 46.746878
D13: 7 | E13: 16.22093 | H13: =E13/$A$44 -> 0.93373494 | M13: =AVERAGE(E13:E27) -> 18.150039 | O13: =$V$2*D13+$V$3 -> 18.043078 | P13: =E13-O13 -> -1.8221475 | Q13: =P13*P13 -> 3.3202216
D14: 8 | E14: 17.790697 | H14: =E14/$A$44 -> 1.0240964 | M14: =AVERAGE(E14:E28) -> 18.682636 | O14: =$V$2*D14+$V$3 -> 18.086196 | P14: =E14-O14 -> -0.29549921 | Q14: =P14*P14 -> 0.087319782
D15: 9 | E15: 33.837208 | H15: =E15/$A$44 -> 1.9477911 | M15: =AVERAGE(E15:E29) -> 18.016434 | O15: =$V$2*D15+$V$3 -> 18.129315 | P15: =E15-O15 -> 15.707893 | Q15: =P15*P15 -> 246.73791
D16: 10 | E16: 6.8023257 | H16: =E16/$A$44 -> 0.39156628 | M16: =AVERAGE(E16:E30) -> 16.639768 | O16: =$V$2*D16+$V$3 -> 18.172434 | P16: =E16-O16 -> -11.370108 | Q16: =P16*P16 -> 129.27935
D17: 11 | E17: 24.244186 | H17: =E17/$A$44 -> 1.3955823 | M17: =AVERAGE(E17:E31) -> 17.320039 | O17: =$V$2*D17+$V$3 -> 18.215552 | P17: =E17-O17 -> 6.0286338 | Q17: =P17*P17 -> 36.344425
D18: 12 | E18: 17.790697 | H18: =E18/$A$44 -> 1.0240964 | M18: =AVERAGE(E18:E32) -> 19.127055 | O18: =$V$2*D18+$V$3 -> 18.258671 | P18: =E18-O18 -> -0.46797392 | Q18: =P18*P18 -> 0.21899959
D19: 13 | E19: 1.0465117 | H19: =E19/$A$44 -> 0.060240969 | M19: =AVERAGE(E19:E33) -> 19.274342 | O19: =$V$2*D19+$V$3 -> 18.30179 | P19: =E19-O19 -> -17.255278 | Q19: =P19*P19 -> 297.74462
D20: 14 | E20: 15.348837 | H20: =E20/$A$44 -> 0.88353414 | M20: =AVERAGE(E20:E34) -> 20.004574 | O20: =$V$2*D20+$V$3 -> 18.344908 | P20: =E20-O20 -> -2.9960713 | Q20: =P20*P20 -> 8.9764431
D21: 15 | E21: 15.174418 | F21: =V3 -> 17.741247 | G21: =V2 -> 0.043118678 | H21: =E21/$A$44 -> 0.87349395 | M21: =AVERAGE(E21:E35) -> 20.181318 | O21: =$V$2*D21+$V$3 -> 18.388027 | P21: =E21-O21 -> -3.213609 | Q21: =P21*P21 -> 10.327283
D22: 16 | E22: 0.6976744 | F22: =$P$2*(E22/H7)+(1-$P$2)*(F21+G21) -> 0.63750801 | G22: =$P$3*(F22-F21)+(1-$P$3)*G21 -> -0.0014651065 | H22: =$P$4*(E22/F22)+(1-$P$4)*H7 -> 1.0943775 | I22: =(F22+(G22))*H7 -> 0.69607102 | J22: =E22-I22 -> 0.0016033795 | K22: =ABS(J22) -> 0.0016033795 | M22: =AVERAGE(E22:E36) -> 20.103024 | O22: =$V$2*D22+$V$3 -> 18.431146 | P22: =E22-O22 -> -17.733471 | Q22: =P22*P22 -> 314.476
D23: 17 | E23: 35.40698 | F23: =$P$2*(E23/H8)+(1-$P$2)*(F22+G22) -> 17.458094 | G23: =$P$3*(F23-F22)+(1-$P$3)*G22 -> 0.042274145 | H23: =$P$4*(E23/F23)+(1-$P$4)*H8 -> 2.0281126 | I23: =(F23+(G23))*H8 -> 35.492717 | J23: =E23-I23 -> -0.085736725 | K23: =ABS(J23) -> 0.085736725 | M23: =AVERAGE(E23:E37) -> 20.589845 | O23: =$V$2*D23+$V$3 -> 18.474264 | P23: =E23-O23 -> 16.932716 | Q23: =P23*P23 -> 286.71686
